Workbook

Sheet Read me
A1: Analysis verification on a small fake grid
A3: What this is | B3: A check of the analysis code (plan/analysis) on a fake grid small enough to follow by hand. Every number the analysis produced is set beside the same number computed here by Excel formulas, from the run table's basic columns and the score sheets, or, for the permutation p values, by counting every possible relabelling.
A4: The fake grid | B4: Two models: gemma-q4 (three arms) and gptoss-20b (two arms, no OFF). Two runs in every task x condition cell (replicates r01 and r02 of the registered schedules), so 12 runs per arm. 64 attempts, 4 of them void, so 60 analysed runs. Every sampled app was graded with a filled score sheet and an API probe file. Made by make_grid.py (the seed and the planted values are written there).
A5: What was planted | B5: SEEN: 5% failure, about 40 steps, apps that work 85% of the time, reasoning on 98% of steps at about 150 characters, no silent turns. UNSEEN: 45% failure, about 70 steps, apps that work 35% of the time, reasoning on 70% of steps at about 400 characters, a silent turn in 40% of runs. OFF: 30% failure, no reasoning. Also 8% void attempts, 20% of runs nudged, 15% of graded apps with a substituted or added package. With 12 runs per arm, only the large effects reach significance, which is what a real test should do.
A6: Colours | B6: Blue text on a light blue fill: a value copied in (from the analysis output, the fake grid's files, or the planted values). Black: an Excel formula. Green 'ok' or 'close': the check passes. Red 'CHECK' or 'not close': look at that row.
A7: Runs | B7: One row per analysed run. Columns A to M are the run table's basic columns. N to U are recomputed by Excel (stratum, failed, log steps, log median, the quality score and API share looked up from the Quality sheet). Then the analysis's own values, then the planted values. Two checks per run: did the analysis read the files correctly (its values equal what was planted), and does Excel's recomputation equal the analysis. On the right, helper columns for the interval check.
A8: Quality | B8: Every graded app's item results, the card's weights and the probe's check results. The score, the substituted flag and the API share are Excel formulas. Void attempts that fell in the quality sample are listed too, marked 'no, a void attempt'.
A9: Voids | B9: Every attempt in the un-blinding key. Excel marks the void ones, checks that each slot has exactly one analysed attempt and that it is never a void one, and counts attempts and voids per model x arm against the analysis's voids table.
A10: Tests | B10: One row per test of the analysis (confirmatory, and the no-nudge and substituted-0 sensitivity reruns). Counts, means and estimates are AVERAGEIFS and COUNTIFS on the Runs sheet. Newcombe intervals (failure, H5) are written out from Wilson's formula and must match exactly. Holm and the verdicts are formulas and must match exactly.
A11: What Excel cannot redo | B11: Two numbers come from random resampling and cannot be repeated exactly by formulas. (1) The permutation p: the analysis tries 10,000 random relabellings. With two runs a cell, every possible relabelling (up to 46,656) can be counted, which gives the exact p. exact_p.py does that, written separately from the analysis code. The analysis's p must lie within Monte Carlo error of the exact p. (2) The bootstrap intervals (steps, quality, H3, H4): Excel computes a normal interval with the same variance the rescaled bootstrap targets (the unbiased stratified variance, from the w helper columns on Runs). With two runs a stratum the bootstrap is lumpy, so the two should be close, not equal.
A12: Summary
A13: check | B13: passed / out of
A14: Runs: read the files right | B14: =COUNTIF(Runs!$AH$2:$AH$61,"ok")&" of 60" -> 60 of 60
A15: Runs: Excel = analysis | B15: =COUNTIF(Runs!$AI$2:$AI$61,"ok")&" of 60" -> 60 of 60
A16: Voids: one analysed attempt per slot | B16: =COUNTIF(Voids!$J$2:$J$65,"ok")&" of 64" -> 64 of 64
A17: Voids: counts per model x arm | B17: =COUNTIF(Voids!$V$3:$V$7,"ok")&" of 5" -> 5 of 5
A18: Tests: counts, means, estimates | B18: =COUNTIF(Tests!$S$2:$S$25,"ok")&" of 24" -> 24 of 24
A19: Tests: Newcombe intervals (exact) | B19: =COUNTIF(Tests!$AC$2:$AC$25,"ok")&" of 7" -> 7 of 7
A20: Tests: bootstrap intervals (close) | B20: =COUNTIF(Tests!$AC$2:$AC$25,"close")&" of 10" -> 10 of 10
A21: Tests: p within Monte Carlo error of exact | B21: =COUNTIF(Tests!$AG$2:$AG$25,"ok")&" of 24" -> 24 of 24
A22: Tests: Holm | B22: =COUNTIF(Tests!$AJ$2:$AJ$25,"ok")&" of 24" -> 24 of 24
A23: Tests: verdicts | B23: =COUNTIF(Tests!$AM$2:$AM$25,"ok")&" of 24" -> 24 of 24
A24: Tests: X | B24: =COUNTIF(Tests!$AP$2:$AP$25,"ok")&" of 24" -> 24 of 24

Sheet Settings
A1: setting | B1: value | C1: where it comes from
A2: alpha | B2: 0.05 | C2: protocol section 8.1, Holm at alpha = 0.05
A3: failure equivalence bound (+/-) | B3: 0.1 | C3: protocol section 8.2, +/-10 percentage points
A4: steps equivalence bound, low | B4: 0.8 | C4: protocol section 8.2
A5: steps equivalence bound, high | B5: 1.25 | C5: protocol section 8.2
A6: permutations | B6: 10000 | C6: protocol section 8.1 (the Monte Carlo p is (1 + hits) / (10,000 + 1))
A7: z for a 95% interval | B7: =NORMSINV(0.975) -> 1.959964 | C7: formula
A8: z for a 90% interval | B8: =NORMSINV(0.95) -> 1.6448536 | C8: formula
A9: tolerance for 6-digit CSV numbers | B9: 1e-05 | C9: the analysis CSVs print 6 significant digits, so matches are checked to a relative 1e-5
A10: interval 'close' tolerance | B10: 0.25 | C10: a bootstrap interval end counts as close to the formula interval's end if they differ by at most this share of the interval's width

Sheet Runs
A1: blind_id | B1: model | C1: task | D1: condition | E1: arm | F1: replicate | G1: status | H1: steps | I1: nudged | J1: reasoning_rate | K1: reasoning_median_chars | L1: silent_turn | M1: sampled | N1: stratum | O1: failed | P1: log_steps | Q1: log_median_chars | R1: quality | S1: quality, substituted scored 0 | T1: substituted | U1: api_conformance | V1: analysis: failed | W1: analysis: log_steps | X1: analysis: log median | Y1: analysis: quality | Z1: analysis: substituted | AA1: analysis: api_conformance | AB1: planted: status | AC1: planted: steps | AD1: planted: reasoning_rate | AE1: planted: median chars | AF1: planted: silent_turn | AG1: planted: nudged | AH1: check: analysis read the files right (vs planted) | AI1: check: Excel recompute = analysis | AK1: steps: has value | AL1: steps: k in stratum | AM1: steps: stratum mean | AN1: steps: w (for the variance) | AO1: quality: has value | AP1: quality: k in stratum | AQ1: quality: stratum mean | AR1: quality: w (for the variance) | AS1: H3: has value | AT1: H3: k in stratum | AU1: H3: stratum mean | AV1: H3: w (for the variance) | AW1: H4: has value | AX1: H4: k in stratum | AY1: H4: stratum mean | AZ1: H4: w (for the variance)
A2: 444173 | B2: gemma-q4 | C2: kanban-board | D2: execution | E2: off | F2: 1 | G2: finished | H2: 41 | I2: 0 | J2: 0 | L2: 0 | M2: 1 | N2: =C2&"|"&D2 -> kanban-board|execution | O2: =IF(G2="finished",0,1) -> 0 | P2: =IF(O2=0,LN(H2),"") -> 3.7135721 | Q2: =IF(ISNUMBER(K2),IF(K2>0,LN(K2),""),"") | R2: =IF(M2=1,INDEX(Quality!$AF:$AF,MATCH(A2,Quality!$A:$A,0)),"") -> 22 | S2: =IF(R2="","",IF(T2=1,0,R2)) -> 0 | T2: =IF(M2=1,INDEX(Quality!$AG:$AG,MATCH(A2,Quality!$A:$A,0)),0) -> 1 | U2: =IF(M2=1,INDEX(Quality!$AS:$AS,MATCH(A2,Quality!$A:$A,0)),"") -> 0.6 | V2: 0 | W2: 3.71357 | Y2: 22 | Z2: 1 | AA2: 0.6 | AB2: finished | AC2: 41 | AD2: 0 | AF2: 0 | AG2: 0 | AH2: =IF(AND(G2=AB2,IF(AND(ISNUMBER(H2),ISNUMBER(AC2)),ABS(N(H2)-N(AC2))<=Settings!$B$9*MAX(1,ABS(N(AC2))),AND(H2="",AC2="")),IF(AND(ISNUMBER(J2),ISNUMBER(AD2)),ABS(N(J2)-N(AD2))<=Settings!$B$9*MAX(1,ABS(N(AD2))),AND(J2="",AD2="")),IF(AND(ISNUMBER(K2),ISNUMBER(AE2)),ABS(N(K2)-N(AE2))<=Settings!$B$9*MAX(1,ABS(N(AE2))),AND(K2="",AE2="")),L2=AF2,I2=AG2),"ok","CHECK") -> ok | AI2: =IF(AND(IF(AND(ISNUMBER(O2),ISNUMBER(V2)),ABS(N(O2)-N(V2))<=Settings!$B$9*MAX(1,ABS(N(V2))),AND(O2="",V2="")),IF(AND(ISNUMBER(P2),ISNUMBER(W2)),ABS(N(P2)-N(W2))<=Settings!$B$9*MAX(1,ABS(N(W2))),AND(P2="",W2="")),IF(AND(ISNUMBER(Q2),ISNUMBER(X2)),ABS(N(Q2)-N(X2))<=Settings!$B$9*MAX(1,ABS(N(X2))),AND(Q2="",X2="")),IF(AND(ISNUMBER(R2),ISNUMBER(Y2)),ABS(N(R2)-N(Y2))<=Settings!$B$9*MAX(1,ABS(N(Y2))),AND(R2="",Y2="")),T2=Z2,IF(AND(ISNUMBER(U2),ISNUMBER(AA2)),ABS(N(U2)-N(AA2))<=Settings!$B$9*MAX(1,ABS(N(AA2))),AND(U2="",AA2=""))),"ok","CHECK") -> ok | AK2: =IF(ISNUMBER(P2),1,0) -> 1 | AL2: =COUNTIFS(Runs!$B$2:$B$61,B2,Runs!$E$2:$E$61,E2,Runs!$N$2:$N$61,N2,Runs!$AK$2:$AK$61,1) -> 2 | AM2: =IF(AK2=1,AVERAGEIFS(Runs!$P$2:$P$61,Runs!$B$2:$B$61,B2,Runs!$E$2:$E$61,E2,Runs!$N$2:$N$61,N2,Runs!$AK$2:$AK$61,1),"") -> 3.7601173 | AN2: =IF(AK2=1,IF(AL2>1,(P2-AM2)^2*AL2/(AL2-1),0),0) -> 0.0043329134 | AO2: =IF(ISNUMBER(R2),1,0) -> 1 | AP2: =COUNTIFS(Runs!$B$2:$B$61,B2,Runs!$E$2:$E$61,E2,Runs!$N$2:$N$61,N2,Runs!$AO$2:$AO$61,1) -> 2 | AQ2: =IF(AO2=1,AVERAGEIFS(Runs!$R$2:$R$61,Runs!$B$2:$B$61,B2,Runs!$E$2:$E$61,E2,Runs!$N$2:$N$61,N2,Runs!$AO$2:$AO$61,1),"") -> 57 | AR2: =IF(AO2=1,IF(AP2>1,(R2-AQ2)^2*AP2/(AP2-1),0),0) -> 2450 | AS2: =IF(ISNUMBER(J2),1,0) -> 1 | AT2: =COUNTIFS(Runs!$B$2:$B$61,B2,Runs!$E$2:$E$61,E2,Runs!$N$2:$N$61,N2,Runs!$AS$2:$AS$61,1) -> 2 | AU2: =IF(AS2=1,AVERAGEIFS(Runs!$J$2:$J$61,Runs!$B$2:$B$61,B2,Runs!$E$2:$E$61,E2,Runs!$N$2:$N$61,N2,Runs!$AS$2:$AS$61,1),"") -> 0 | AV2: =IF(AS2=1,IF(AT2>1,(J2-AU2)^2*AT2/(AT2-1),0),0) -> 0 | AW2: =IF(ISNUMBER(Q2),1,0) -> 0 | AX2: =COUNTIFS(Runs!$B$2:$B$61,B2,Runs!$E$2:$E$61,E2,Runs!$N$2:$N$61,N2,Runs!$AW$2:$AW$61,1) -> 0 | AY2: =IF(AW2=1,AVERAGEIFS(Runs!$Q$2:$Q$61,Runs!$B$2:$B$61,B2,Runs!$E$2:$E$61,E2,Runs!$N$2:$N$61,N2,Runs!$AW$2:$AW$61,1),"") | AZ2: =IF(AW2=1,IF(AX2>1,(Q2-AY2)^2*AX2/(AX2-1),0),0) -> 0
A3: 750607 | B3: gemma-q4 | C3: kanban-board | D3: execution | E3: off | F3: 2 | G3: finished | H3: 45 | I3: 0 | J3: 0 | L3: 0 | M3: 1 | N3: =C3&"|"&D3 -> kanban-board|execution | O3: =IF(G3="finished",0,1) -> 0 | P3: =IF(O3=0,LN(H3),"") -> 3.8066625 | Q3: =IF(ISNUMBER(K3),IF(K3>0,LN(K3),""),"") | R3: =IF(M3=1,INDEX(Quality!$AF:$AF,MATCH(A3,Quality!$A:$A,0)),"") -> 92 | S3: =IF(R3="","",IF(T3=1,0,R3)) -> 92 | T3: =IF(M3=1,INDEX(Quality!$AG:$AG,MATCH(A3,Quality!$A:$A,0)),0) -> 0 | U3: =IF(M3=1,INDEX(Quality!$AS:$AS,MATCH(A3,Quality!$A:$A,0)),"") -> 0.5 | V3: 0 | W3: 3.80666 | Y3: 92 | Z3: 0 | AA3: 0.5 | AB3: finished | AC3: 45 | AD3: 0 | AF3: 0 | AG3: 0 | AH3: =IF(AND(G3=AB3,IF(AND(ISNUMBER(H3),ISNUMBER(AC3)),ABS(N(H3)-N(AC3))<=Settings!$B$9*MAX(1,ABS(N(AC3))),AND(H3="",AC3="")),IF(AND(ISNUMBER(J3),ISNUMBER(AD3)),ABS(N(J3)-N(AD3))<=Settings!$B$9*MAX(1,ABS(N(AD3))),AND(J3="",AD3="")),IF(AND(ISNUMBER(K3),ISNUMBER(AE3)),ABS(N(K3)-N(AE3))<=Settings!$B$9*MAX(1,ABS(N(AE3))),AND(K3="",AE3="")),L3=AF3,I3=AG3),"ok","CHECK") -> ok | AI3: =IF(AND(IF(AND(ISNUMBER(O3),ISNUMBER(V3)),ABS(N(O3)-N(V3))<=Settings!$B$9*MAX(1,ABS(N(V3))),AND(O3="",V3="")),IF(AND(ISNUMBER(P3),ISNUMBER(W3)),ABS(N(P3)-N(W3))<=Settings!$B$9*MAX(1,ABS(N(W3))),AND(P3="",W3="")),IF(AND(ISNUMBER(Q3),ISNUMBER(X3)),ABS(N(Q3)-N(X3))<=Settings!$B$9*MAX(1,ABS(N(X3))),AND(Q3="",X3="")),IF(AND(ISNUMBER(R3),ISNUMBER(Y3)),ABS(N(R3)-N(Y3))<=Settings!$B$9*MAX(1,ABS(N(Y3))),AND(R3="",Y3="")),T3=Z3,IF(AND(ISNUMBER(U3),ISNUMBER(AA3)),ABS(N(U3)-N(AA3))<=Settings!$B$9*MAX(1,ABS(N(AA3))),AND(U3="",AA3=""))),"ok","CHECK") -> ok | AK3: =IF(ISNUMBER(P3),1,0) -> 1 | AL3: =COUNTIFS(Runs!$B$2:$B$61,B3,Runs!$E$2:$E$61,E3,Runs!$N$2:$N$61,N3,Runs!$AK$2:$AK$61,1) -> 2 | AM3: =IF(AK3=1,AVERAGEIFS(Runs!$P$2:$P$61,Runs!$B$2:$B$61,B3,Runs!$E$2:$E$61,E3,Runs!$N$2:$N$61,N3,Runs!$AK$2:$AK$61,1),"") -> 3.7601173 | AN3: =IF(AK3=1,IF(AL3>1,(P3-AM3)^2*AL3/(AL3-1),0),0) -> 0.0043329134 | AO3: =IF(ISNUMBER(R3),1,0) -> 1 | AP3: =COUNTIFS(Runs!$B$2:$B$61,B3,Runs!$E$2:$E$61,E3,Runs!$N$2:$N$61,N3,Runs!$AO$2:$AO$61,1) -> 2 | AQ3: =IF(AO3=1,AVERAGEIFS(Runs!$R$2:$R$61,Runs!$B$2:$B$61,B3,Runs!$E$2:$E$61,E3,Runs!$N$2:$N$61,N3,Runs!$AO$2:$AO$61,1),"") -> 57 | AR3: =IF(AO3=1,IF(AP3>1,(R3-AQ3)^2*AP3/(AP3-1),0),0) -> 2450 | AS3: =IF(ISNUMBER(J3),1,0) -> 1 | AT3: =COUNTIFS(Runs!$B$2:$B$61,B3,Runs!$E$2:$E$61,E3,Runs!$N$2:$N$61,N3,Runs!$AS$2:$AS$61,1) -> 2 | AU3: =IF(AS3=1,AVERAGEIFS(Runs!$J$2:$J$61,Runs!$B$2:$B$61,B3,Runs!$E$2:$E$61,E3,Runs!$N$2:$N$61,N3,Runs!$AS$2:$AS$61,1),"") -> 0 | AV3: =IF(AS3=1,IF(AT3>1,(J3-AU3)^2*AT3/(AT3-1),0),0) -> 0 | AW3: =IF(ISNUMBER(Q3),1,0) -> 0 | AX3: =COUNTIFS(Runs!$B$2:$B$61,B3,Runs!$E$2:$E$61,E3,Runs!$N$2:$N$61,N3,Runs!$AW$2:$AW$61,1) -> 0 | AY3: =IF(AW3=1,AVERAGEIFS(Runs!$Q$2:$Q$61,Runs!$B$2:$B$61,B3,Runs!$E$2:$E$61,E3,Runs!$N$2:$N$61,N3,Runs!$AW$2:$AW$61,1),"") | AZ3: =IF(AW3=1,IF(AX3>1,(Q3-AY3)^2*AX3/(AX3-1),0),0) -> 0
A4: 492366 | B4: gemma-q4 | C4: kanban-board | D4: execution | E4: unseen | F4: 1 | G4: finished | H4: 50 | I4: 0 | J4: 0.7 | K4: 440 | L4: 0 | M4: 1 | N4: =C4&"|"&D4 -> kanban-board|execution | O4: =IF(G4="finished",0,1) -> 0 | P4: =IF(O4=0,LN(H4),"") -> 3.912023 | Q4: =IF(ISNUMBER(K4),IF(K4>0,LN(K4),""),"") -> 6.0867747 | R4: =IF(M4=1,INDEX(Quality!$AF:$AF,MATCH(A4,Quality!$A:$A,0)),"") -> 14 | S4: =IF(R4="","",IF(T4=1,0,R4)) -> 14 | T4: =IF(M4=1,INDEX(Quality!$AG:$AG,MATCH(A4,Quality!$A:$A,0)),0) -> 0 | U4: =IF(M4=1,INDEX(Quality!$AS:$AS,MATCH(A4,Quality!$A:$A,0)),"") -> 0.6 | V4: 0 | W4: 3.91202 | X4: 6.08677 | Y4: 14 | Z4: 0 | AA4: 0.6 | AB4: finished | AC4: 50 | AD4: 0.7 | AE4: 440 | AF4: 0 | AG4: 0 | AH4: =IF(AND(G4=AB4,IF(AND(ISNUMBER(H4),ISNUMBER(AC4)),ABS(N(H4)-N(AC4))<=Settings!$B$9*MAX(1,ABS(N(AC4))),AND(H4="",AC4="")),IF(AND(ISNUMBER(J4),ISNUMBER(AD4)),ABS(N(J4)-N(AD4))<=Settings!$B$9*MAX(1,ABS(N(AD4))),AND(J4="",AD4="")),IF(AND(ISNUMBER(K4),ISNUMBER(AE4)),ABS(N(K4)-N(AE4))<=Settings!$B$9*MAX(1,ABS(N(AE4))),AND(K4="",AE4="")),L4=AF4,I4=AG4),"ok","CHECK") -> ok | AI4: =IF(AND(IF(AND(ISNUMBER(O4),ISNUMBER(V4)),ABS(N(O4)-N(V4))<=Settings!$B$9*MAX(1,ABS(N(V4))),AND(O4="",V4="")),IF(AND(ISNUMBER(P4),ISNUMBER(W4)),ABS(N(P4)-N(W4))<=Settings!$B$9*MAX(1,ABS(N(W4))),AND(P4="",W4="")),IF(AND(ISNUMBER(Q4),ISNUMBER(X4)),ABS(N(Q4)-N(X4))<=Settings!$B$9*MAX(1,ABS(N(X4))),AND(Q4="",X4="")),IF(AND(ISNUMBER(R4),ISNUMBER(Y4)),ABS(N(R4)-N(Y4))<=Settings!$B$9*MAX(1,ABS(N(Y4))),AND(R4="",Y4="")),T4=Z4,IF(AND(ISNUMBER(U4),ISNUMBER(AA4)),ABS(N(U4)-N(AA4))<=Settings!$B$9*MAX(1,ABS(N(AA4))),AND(U4="",AA4=""))),"ok","CHECK") -> ok | AK4: =IF(ISNUMBER(P4),1,0) -> 1 | AL4: =COUNTIFS(Runs!$B$2:$B$61,B4,Runs!$E$2:$E$61,E4,Runs!$N$2:$N$61,N4,Runs!$AK$2:$AK$61,1) -> 1 | AM4: =IF(AK4=1,AVERAGEIFS(Runs!$P$2:$P$61,Runs!$B$2:$B$61,B4,Runs!$E$2:$E$61,E4,Runs!$N$2:$N$61,N4,Runs!$AK$2:$AK$61,1),"") -> 3.912023 | AN4: =IF(AK4=1,IF(AL4>1,(P4-AM4)^2*AL4/(AL4-1),0),0) -> 0 | AO4: =IF(ISNUMBER(R4),1,0) -> 1 | AP4: =COUNTIFS(Runs!$B$2:$B$61,B4,Runs!$E$2:$E$61,E4,Runs!$N$2:$N$61,N4,Runs!$AO$2:$AO$61,1) -> 2 | AQ4: =IF(AO4=1,AVERAGEIFS(Runs!$R$2:$R$61,Runs!$B$2:$B$61,B4,Runs!$E$2:$E$61,E4,Runs!$N$2:$N$61,N4,Runs!$AO$2:$AO$61,1),"") -> 8 | AR4: =IF(AO4=1,IF(AP4>1,(R4-AQ4)^2*AP4/(AP4-1),0),0) -> 72 | AS4: =IF(ISNUMBER(J4),1,0) -> 1 | AT4: =COUNTIFS(Runs!$B$2:$B$61,B4,Runs!$E$2:$E$61,E4,Runs!$N$2:$N$61,N4,Runs!$AS$2:$AS$61,1) -> 2 | AU4: =IF(AS4=1,AVERAGEIFS(Runs!$J$2:$J$61,Runs!$B$2:$B$61,B4,Runs!$E$2:$E$61,E4,Runs!$N$2:$N$61,N4,Runs!$AS$2:$AS$61,1),"") -> 0.71875 | AV4: =IF(AS4=1,IF(AT4>1,(J4-AU4)^2*AT4/(AT4-1),0),0) -> 0.000703125 | AW4: =IF(ISNUMBER(Q4),1,0) -> 1 | AX4: =COUNTIFS(Runs!$B$2:$B$61,B4,Runs!$E$2:$E$61,E4,Runs!$N$2:$N$61,N4,Runs!$AW$2:$AW$61,1) -> 2 | AY4: =IF(AW4=1,AVERAGEIFS(Runs!$Q$2:$Q$61,Runs!$B$2:$B$61,B4,Runs!$E$2:$E$61,E4,Runs!$N$2:$N$61,N4,Runs!$AW$2:$AW$61,1),"") -> 6.00951 | AZ4: =IF(AW4=1,IF(AX4>1,(Q4-AY4)^2*AX4/(AX4-1),0),0) -> 0.011939689
A5: 990307 | B5: gemma-q4 | C5: kanban-board | D5: execution | E5: unseen | F5: 2 | G5: truncated_tool_args | H5: 80 | I5: 0 | J5: 0.7375 | K5: 377 | L5: 0 | M5: 1 | N5: =C5&"|"&D5 -> kanban-board|execution | O5: =IF(G5="finished",0,1) -> 1 | P5: =IF(O5=0,LN(H5),"") | Q5: =IF(ISNUMBER(K5),IF(K5>0,LN(K5),""),"") -> 5.9322452 | R5: =IF(M5=1,INDEX(Quality!$AF:$AF,MATCH(A5,Quality!$A:$A,0)),"") -> 2 | S5: =IF(R5="","",IF(T5=1,0,R5)) -> 2 | T5: =IF(M5=1,INDEX(Quality!$AG:$AG,MATCH(A5,Quality!$A:$A,0)),0) -> 0 | U5: =IF(M5=1,INDEX(Quality!$AS:$AS,MATCH(A5,Quality!$A:$A,0)),"") -> 0.7 | V5: 1 | X5: 5.93225 | Y5: 2 | Z5: 0 | AA5: 0.7 | AB5: truncated_tool_args | AC5: 80 | AD5: 0.7375 | AE5: 377 | AF5: 0 | AG5: 0 | AH5: =IF(AND(G5=AB5,IF(AND(ISNUMBER(H5),ISNUMBER(AC5)),ABS(N(H5)-N(AC5))<=Settings!$B$9*MAX(1,ABS(N(AC5))),AND(H5="",AC5="")),IF(AND(ISNUMBER(J5),ISNUMBER(AD5)),ABS(N(J5)-N(AD5))<=Settings!$B$9*MAX(1,ABS(N(AD5))),AND(J5="",AD5="")),IF(AND(ISNUMBER(K5),ISNUMBER(AE5)),ABS(N(K5)-N(AE5))<=Settings!$B$9*MAX(1,ABS(N(AE5))),AND(K5="",AE5="")),L5=AF5,I5=AG5),"ok","CHECK") -> ok | AI5: =IF(AND(IF(AND(ISNUMBER(O5),ISNUMBER(V5)),ABS(N(O5)-N(V5))<=Settings!$B$9*MAX(1,ABS(N(V5))),AND(O5="",V5="")),IF(AND(ISNUMBER(P5),ISNUMBER(W5)),ABS(N(P5)-N(W5))<=Settings!$B$9*MAX(1,ABS(N(W5))),AND(P5="",W5="")),IF(AND(ISNUMBER(Q5),ISNUMBER(X5)),ABS(N(Q5)-N(X5))<=Settings!$B$9*MAX(1,ABS(N(X5))),AND(Q5="",X5="")),IF(AND(ISNUMBER(R5),ISNUMBER(Y5)),ABS(N(R5)-N(Y5))<=Settings!$B$9*MAX(1,ABS(N(Y5))),AND(R5="",Y5="")),T5=Z5,IF(AND(ISNUMBER(U5),ISNUMBER(AA5)),ABS(N(U5)-N(AA5))<=Settings!$B$9*MAX(1,ABS(N(AA5))),AND(U5="",AA5=""))),"ok","CHECK") -> ok | AK5: =IF(ISNUMBER(P5),1,0) -> 0 | AL5: =COUNTIFS(Runs!$B$2:$B$61,B5,Runs!$E$2:$E$61,E5,Runs!$N$2:$N$61,N5,Runs!$AK$2:$AK$61,1) -> 1 | AM5: =IF(AK5=1,AVERAGEIFS(Runs!$P$2:$P$61,Runs!$B$2:$B$61,B5,Runs!$E$2:$E$61,E5,Runs!$N$2:$N$61,N5,Runs!$AK$2:$AK$61,1),"") | AN5: =IF(AK5=1,IF(AL5>1,(P5-AM5)^2*AL5/(AL5-1),0),0) -> 0 | AO5: =IF(ISNUMBER(R5),1,0) -> 1 | AP5: =COUNTIFS(Runs!$B$2:$B$61,B5,Runs!$E$2:$E$61,E5,Runs!$N$2:$N$61,N5,Runs!$AO$2:$AO$61,1) -> 2 | AQ5: =IF(AO5=1,AVERAGEIFS(Runs!$R$2:$R$61,Runs!$B$2:$B$61,B5,Runs!$E$2:$E$61,E5,Runs!$N$2:$N$61,N5,Runs!$AO$2:$AO$61,1),"") -> 8 | AR5: =IF(AO5=1,IF(AP5>1,(R5-AQ5)^2*AP5/(AP5-1),0),0) -> 72 | AS5: =IF(ISNUMBER(J5),1,0) -> 1 | AT5: =COUNTIFS(Runs!$B$2:$B$61,B5,Runs!$E$2:$E$61,E5,Runs!$N$2:$N$61,N5,Runs!$AS$2:$AS$61,1) -> 2 | AU5: =IF(AS5=1,AVERAGEIFS(Runs!$J$2:$J$61,Runs!$B$2:$B$61,B5,Runs!$E$2:$E$61,E5,Runs!$N$2:$N$61,N5,Runs!$AS$2:$AS$61,1),"") -> 0.71875 | AV5: =IF(AS5=1,IF(AT5>1,(J5-AU5)^2*AT5/(AT5-1),0),0) -> 0.000703125 | AW5: =IF(ISNUMBER(Q5),1,0) -> 1 | AX5: =COUNTIFS(Runs!$B$2:$B$61,B5,Runs!$E$2:$E$61,E5,Runs!$N$2:$N$61,N5,Runs!$AW$2:$AW$61,1) -> 2 | AY5: =IF(AW5=1,AVERAGEIFS(Runs!$Q$2:$Q$61,Runs!$B$2:$B$61,B5,Runs!$E$2:$E$61,E5,Runs!$N$2:$N$61,N5,Runs!$AW$2:$AW$61,1),"") -> 6.00951 | AZ5: =IF(AW5=1,IF(AX5>1,(Q5-AY5)^2*AX5/(AX5-1),0),0) -> 0.011939689
A6: 232514 | B6: gemma-q4 | C6: kanban-board | D6: execution | E6: seen | F6: 1 | G6: finished | H6: 42 | I6: 0 | J6: 0.97619 | K6: 131 | L6: 0 | M6: 1 | N6: =C6&"|"&D6 -> kanban-board|execution | O6: =IF(G6="finished",0,1) -> 0 | P6: =IF(O6=0,LN(H6),"") -> 3.7376696 | Q6: =IF(ISNUMBER(K6),IF(K6>0,LN(K6),""),"") -> 4.8751973 | R6: =IF(M6=1,INDEX(Quality!$AF:$AF,MATCH(A6,Quality!$A:$A,0)),"") -> 80 | S6: =IF(R6="","",IF(T6=1,0,R6)) -> 80 | T6: =IF(M6=1,INDEX(Quality!$AG:$AG,MATCH(A6,Quality!$A:$A,0)),0) -> 0 | U6: =IF(M6=1,INDEX(Quality!$AS:$AS,MATCH(A6,Quality!$A:$A,0)),"") -> 0.7 | V6: 0 | W6: 3.73767 | X6: 4.8752 | Y6: 80 | Z6: 0 | AA6: 0.7 | AB6: finished | AC6: 42 | AD6: 0.97619048 | AE6: 131 | AF6: 0 | AG6: 0 | AH6: =IF(AND(G6=AB6,IF(AND(ISNUMBER(H6),ISNUMBER(AC6)),ABS(N(H6)-N(AC6))<=Settings!$B$9*MAX(1,ABS(N(AC6))),AND(H6="",AC6="")),IF(AND(ISNUMBER(J6),ISNUMBER(AD6)),ABS(N(J6)-N(AD6))<=Settings!$B$9*MAX(1,ABS(N(AD6))),AND(J6="",AD6="")),IF(AND(ISNUMBER(K6),ISNUMBER(AE6)),ABS(N(K6)-N(AE6))<=Settings!$B$9*MAX(1,ABS(N(AE6))),AND(K6="",AE6="")),L6=AF6,I6=AG6),"ok","CHECK") -> ok | AI6: =IF(AND(IF(AND(ISNUMBER(O6),ISNUMBER(V6)),ABS(N(O6)-N(V6))<=Settings!$B$9*MAX(1,ABS(N(V6))),AND(O6="",V6="")),IF(AND(ISNUMBER(P6),ISNUMBER(W6)),ABS(N(P6)-N(W6))<=Settings!$B$9*MAX(1,ABS(N(W6))),AND(P6="",W6="")),IF(AND(ISNUMBER(Q6),ISNUMBER(X6)),ABS(N(Q6)-N(X6))<=Settings!$B$9*MAX(1,ABS(N(X6))),AND(Q6="",X6="")),IF(AND(ISNUMBER(R6),ISNUMBER(Y6)),ABS(N(R6)-N(Y6))<=Settings!$B$9*MAX(1,ABS(N(Y6))),AND(R6="",Y6="")),T6=Z6,IF(AND(ISNUMBER(U6),ISNUMBER(AA6)),ABS(N(U6)-N(AA6))<=Settings!$B$9*MAX(1,ABS(N(AA6))),AND(U6="",AA6=""))),"ok","CHECK") -> ok | AK6: =IF(ISNUMBER(P6),1,0) -> 1 | AL6: =COUNTIFS(Runs!$B$2:$B$61,B6,Runs!$E$2:$E$61,E6,Runs!$N$2:$N$61,N6,Runs!$AK$2:$AK$61,1) -> 2 | AM6: =IF(AK6=1,AVERAGEIFS(Runs!$P$2:$P$61,Runs!$B$2:$B$61,B6,Runs!$E$2:$E$61,E6,Runs!$N$2:$N$61,N6,Runs!$AK$2:$AK$61,1),"") -> 3.4978831 | AN6: =IF(AK6=1,IF(AL6>1,(P6-AM6)^2*AL6/(AL6-1),0),0) -> 0.11499517 | AO6: =IF(ISNUMBER(R6),1,0) -> 1 | AP6: =COUNTIFS(Runs!$B$2:$B$61,B6,Runs!$E$2:$E$61,E6,Runs!$N$2:$N$61,N6,Runs!$AO$2:$AO$61,1) -> 2 | AQ6: =IF(AO6=1,AVERAGEIFS(Runs!$R$2:$R$61,Runs!$B$2:$B$61,B6,Runs!$E$2:$E$61,E6,Runs!$N$2:$N$61,N6,Runs!$AO$2:$AO$61,1),"") -> 83 | AR6: =IF(AO6=1,IF(AP6>1,(R6-AQ6)^2*AP6/(AP6-1),0),0) -> 18 | AS6: =IF(ISNUMBER(J6),1,0) -> 1 | AT6: =COUNTIFS(Runs!$B$2:$B$61,B6,Runs!$E$2:$E$61,E6,Runs!$N$2:$N$61,N6,Runs!$AS$2:$AS$61,1) -> 2 | AU6: =IF(AS6=1,AVERAGEIFS(Runs!$J$2:$J$61,Runs!$B$2:$B$61,B6,Runs!$E$2:$E$61,E6,Runs!$N$2:$N$61,N6,Runs!$AS$2:$AS$61,1),"") -> 0.988095 | AV6: =IF(AS6=1,IF(AT6>1,(J6-AU6)^2*AT6/(AT6-1),0),0) -> 0.00028345805 | AW6: =IF(ISNUMBER(Q6),1,0) -> 1 | AX6: =COUNTIFS(Runs!$B$2:$B$61,B6,Runs!$E$2:$E$61,E6,Runs!$N$2:$N$61,N6,Runs!$AW$2:$AW$61,1) -> 2 | AY6: =IF(AW6=1,AVERAGEIFS(Runs!$Q$2:$Q$61,Runs!$B$2:$B$61,B6,Runs!$E$2:$E$61,E6,Runs!$N$2:$N$61,N6,Runs!$AW$2:$AW$61,1),"") -> 4.9720508 | AZ6: =IF(AW6=1,IF(AX6>1,(Q6-AY6)^2*AX6/(AX6-1),0),0) -> 0.018761177
A7: 207060 | B7: gemma-q4 | C7: kanban-board | D7: execution | E7: seen | F7: 2 | G7: finished | H7: 26 | I7: 1 | J7: 1 | K7: 159 | L7: 0 | M7: 1 | N7: =C7&"|"&D7 -> kanban-board|execution | O7: =IF(G7="finished",0,1) -> 0 | P7: =IF(O7=0,LN(H7),"") -> 3.2580965 | Q7: =IF(ISNUMBER(K7),IF(K7>0,LN(K7),""),"") -> 5.0689042 | R7: =IF(M7=1,INDEX(Quality!$AF:$AF,MATCH(A7,Quality!$A:$A,0)),"") -> 86 | S7: =IF(R7="","",IF(T7=1,0,R7)) -> 86 | T7: =IF(M7=1,INDEX(Quality!$AG:$AG,MATCH(A7,Quality!$A:$A,0)),0) -> 0 | U7: =IF(M7=1,INDEX(Quality!$AS:$AS,MATCH(A7,Quality!$A:$A,0)),"") -> 0.7 | V7: 0 | W7: 3.2581 | X7: 5.0689 | Y7: 86 | Z7: 0 | AA7: 0.7 | AB7: finished | AC7: 26 | AD7: 1 | AE7: 159 | AF7: 0 | AG7: 1 | AH7: =IF(AND(G7=AB7,IF(AND(ISNUMBER(H7),ISNUMBER(AC7)),ABS(N(H7)-N(AC7))<=Settings!$B$9*MAX(1,ABS(N(AC7))),AND(H7="",AC7="")),IF(AND(ISNUMBER(J7),ISNUMBER(AD7)),ABS(N(J7)-N(AD7))<=Settings!$B$9*MAX(1,ABS(N(AD7))),AND(J7="",AD7="")),IF(AND(ISNUMBER(K7),ISNUMBER(AE7)),ABS(N(K7)-N(AE7))<=Settings!$B$9*MAX(1,ABS(N(AE7))),AND(K7="",AE7="")),L7=AF7,I7=AG7),"ok","CHECK") -> ok | AI7: =IF(AND(IF(AND(ISNUMBER(O7),ISNUMBER(V7)),ABS(N(O7)-N(V7))<=Settings!$B$9*MAX(1,ABS(N(V7))),AND(O7="",V7="")),IF(AND(ISNUMBER(P7),ISNUMBER(W7)),ABS(N(P7)-N(W7))<=Settings!$B$9*MAX(1,ABS(N(W7))),AND(P7="",W7="")),IF(AND(ISNUMBER(Q7),ISNUMBER(X7)),ABS(N(Q7)-N(X7))<=Settings!$B$9*MAX(1,ABS(N(X7))),AND(Q7="",X7="")),IF(AND(ISNUMBER(R7),ISNUMBER(Y7)),ABS(N(R7)-N(Y7))<=Settings!$B$9*MAX(1,ABS(N(Y7))),AND(R7="",Y7="")),T7=Z7,IF(AND(ISNUMBER(U7),ISNUMBER(AA7)),ABS(N(U7)-N(AA7))<=Settings!$B$9*MAX(1,ABS(N(AA7))),AND(U7="",AA7=""))),"ok","CHECK") -> ok | AK7: =IF(ISNUMBER(P7),1,0) -> 1 | AL7: =COUNTIFS(Runs!$B$2:$B$61,B7,Runs!$E$2:$E$61,E7,Runs!$N$2:$N$61,N7,Runs!$AK$2:$AK$61,1) -> 2 | AM7: =IF(AK7=1,AVERAGEIFS(Runs!$P$2:$P$61,Runs!$B$2:$B$61,B7,Runs!$E$2:$E$61,E7,Runs!$N$2:$N$61,N7,Runs!$AK$2:$AK$61,1),"") -> 3.4978831 | AN7: =IF(AK7=1,IF(AL7>1,(P7-AM7)^2*AL7/(AL7-1),0),0) -> 0.11499517 | AO7: =IF(ISNUMBER(R7),1,0) -> 1 | AP7: =COUNTIFS(Runs!$B$2:$B$61,B7,Runs!$E$2:$E$61,E7,Runs!$N$2:$N$61,N7,Runs!$AO$2:$AO$61,1) -> 2 | AQ7: =IF(AO7=1,AVERAGEIFS(Runs!$R$2:$R$61,Runs!$B$2:$B$61,B7,Runs!$E$2:$E$61,E7,Runs!$N$2:$N$61,N7,Runs!$AO$2:$AO$61,1),"") -> 83 | AR7: =IF(AO7=1,IF(AP7>1,(R7-AQ7)^2*AP7/(AP7-1),0),0) -> 18 | AS7: =IF(ISNUMBER(J7),1,0) -> 1 | AT7: =COUNTIFS(Runs!$B$2:$B$61,B7,Runs!$E$2:$E$61,E7,Runs!$N$2:$N$61,N7,Runs!$AS$2:$AS$61,1) -> 2 | AU7: =IF(AS7=1,AVERAGEIFS(Runs!$J$2:$J$61,Runs!$B$2:$B$61,B7,Runs!$E$2:$E$61,E7,Runs!$N$2:$N$61,N7,Runs!$AS$2:$AS$61,1),"") -> 0.988095 | AV7: =IF(AS7=1,IF(AT7>1,(J7-AU7)^2*AT7/(AT7-1),0),0) -> 0.00028345805 | AW7: =IF(ISNUMBER(Q7),1,0) -> 1 | AX7: =COUNTIFS(Runs!$B$2:$B$61,B7,Runs!$E$2:$E$61,E7,Runs!$N$2:$N$61,N7,Runs!$AW$2:$AW$61,1) -> 2 | AY7: =IF(AW7=1,AVERAGEIFS(Runs!$Q$2:$Q$61,Runs!$B$2:$B$61,B7,Runs!$E$2:$E$61,E7,Runs!$N$2:$N$61,N7,Runs!$AW$2:$AW$61,1),"") -> 4.9720508 | AZ7: =IF(AW7=1,IF(AX7>1,(Q7-AY7)^2*AX7/(AX7-1),0),0) -> 0.018761177
A8: 627658 | B8: gemma-q4 | C8: kanban-board | D8: interactive | E8: off | F8: 1 | G8: finished | H8: 23 | I8: 1 | J8: 0 | L8: 0 | M8: 1 | N8: =C8&"|"&D8 -> kanban-board|interactive | O8: =IF(G8="finished",0,1) -> 0 | P8: =IF(O8=0,LN(H8),"") -> 3.1354942 | Q8: =IF(ISNUMBER(K8),IF(K8>0,LN(K8),""),"") | R8: =IF(M8=1,INDEX(Quality!$AF:$AF,MATCH(A8,Quality!$A:$A,0)),"") -> 94 | S8: =IF(R8="","",IF(T8=1,0,R8)) -> 94 | T8: =IF(M8=1,INDEX(Quality!$AG:$AG,MATCH(A8,Quality!$A:$A,0)),0) -> 0 | U8: =IF(M8=1,INDEX(Quality!$AS:$AS,MATCH(A8,Quality!$A:$A,0)),"") -> 0.6 | V8: 0 | W8: 3.13549 | Y8: 94 | Z8: 0 | AA8: 0.6 | AB8: finished | AC8: 23 | AD8: 0 | AF8: 0 | AG8: 1 | AH8: =IF(AND(G8=AB8,IF(AND(ISNUMBER(H8),ISNUMBER(AC8)),ABS(N(H8)-N(AC8))<=Settings!$B$9*MAX(1,ABS(N(AC8))),AND(H8="",AC8="")),IF(AND(ISNUMBER(J8),ISNUMBER(AD8)),ABS(N(J8)-N(AD8))<=Settings!$B$9*MAX(1,ABS(N(AD8))),AND(J8="",AD8="")),IF(AND(ISNUMBER(K8),ISNUMBER(AE8)),ABS(N(K8)-N(AE8))<=Settings!$B$9*MAX(1,ABS(N(AE8))),AND(K8="",AE8="")),L8=AF8,I8=AG8),"ok","CHECK") -> ok | AI8: =IF(AND(IF(AND(ISNUMBER(O8),ISNUMBER(V8)),ABS(N(O8)-N(V8))<=Settings!$B$9*MAX(1,ABS(N(V8))),AND(O8="",V8="")),IF(AND(ISNUMBER(P8),ISNUMBER(W8)),ABS(N(P8)-N(W8))<=Settings!$B$9*MAX(1,ABS(N(W8))),AND(P8="",W8="")),IF(AND(ISNUMBER(Q8),ISNUMBER(X8)),ABS(N(Q8)-N(X8))<=Settings!$B$9*MAX(1,ABS(N(X8))),AND(Q8="",X8="")),IF(AND(ISNUMBER(R8),ISNUMBER(Y8)),ABS(N(R8)-N(Y8))<=Settings!$B$9*MAX(1,ABS(N(Y8))),AND(R8="",Y8="")),T8=Z8,IF(AND(ISNUMBER(U8),ISNUMBER(AA8)),ABS(N(U8)-N(AA8))<=Settings!$B$9*MAX(1,ABS(N(AA8))),AND(U8="",AA8=""))),"ok","CHECK") -> ok | AK8: =IF(ISNUMBER(P8),1,0) -> 1 | AL8: =COUNTIFS(Runs!$B$2:$B$61,B8,Runs!$E$2:$E$61,E8,Runs!$N$2:$N$61,N8,Runs!$AK$2:$AK$61,1) -> 2 | AM8: =IF(AK8=1,AVERAGEIFS(Runs!$P$2:$P$61,Runs!$B$2:$B$61,B8,Runs!$E$2:$E$61,E8,Runs!$N$2:$N$61,N8,Runs!$AK$2:$AK$61,1),"") -> 3.8064155 | AN8: =IF(AK8=1,IF(AL8>1,(P8-AM8)^2*AL8/(AL8-1),0),0) -> 0.90027078 | AO8: =IF(ISNUMBER(R8),1,0) -> 1 | AP8: =COUNTIFS(Runs!$B$2:$B$61,B8,Runs!$E$2:$E$61,E8,Runs!$N$2:$N$61,N8,Runs!$AO$2:$AO$61,1) -> 2 | AQ8: =IF(AO8=1,AVERAGEIFS(Runs!$R$2:$R$61,Runs!$B$2:$B$61,B8,Runs!$E$2:$E$61,E8,Runs!$N$2:$N$61,N8,Runs!$AO$2:$AO$61,1),"") -> 92 | AR8: =IF(AO8=1,IF(AP8>1,(R8-AQ8)^2*AP8/(AP8-1),0),0) -> 8 | AS8: =IF(ISNUMBER(J8),1,0) -> 1 | AT8: =COUNTIFS(Runs!$B$2:$B$61,B8,Runs!$E$2:$E$61,E8,Runs!$N$2:$N$61,N8,Runs!$AS$2:$AS$61,1) -> 2 | AU8: =IF(AS8=1,AVERAGEIFS(Runs!$J$2:$J$61,Runs!$B$2:$B$61,B8,Runs!$E$2:$E$61,E8,Runs!$N$2:$N$61,N8,Runs!$AS$2:$AS$61,1),"") -> 0 | AV8: =IF(AS8=1,IF(AT8>1,(J8-AU8)^2*AT8/(AT8-1),0),0) -> 0 | AW8: =IF(ISNUMBER(Q8),1,0) -> 0 | AX8: =COUNTIFS(Runs!$B$2:$B$61,B8,Runs!$E$2:$E$61,E8,Runs!$N$2:$N$61,N8,Runs!$AW$2:$AW$61,1) -> 0 | AY8: =IF(AW8=1,AVERAGEIFS(Runs!$Q$2:$Q$61,Runs!$B$2:$B$61,B8,Runs!$E$2:$E$61,E8,Runs!$N$2:$N$61,N8,Runs!$AW$2:$AW$61,1),"") | AZ8: =IF(AW8=1,IF(AX8>1,(Q8-AY8)^2*AX8/(AX8-1),0),0) -> 0
A9: 605277 | B9: gemma-q4 | C9: kanban-board | D9: interactive | E9: off | F9: 2 | G9: finished | H9: 88 | I9: 0 | J9: 0 | L9: 0 | M9: 1 | N9: =C9&"|"&D9 -> kanban-board|interactive | O9: =IF(G9="finished",0,1) -> 0 | P9: =IF(O9=0,LN(H9),"") -> 4.4773368 | Q9: =IF(ISNUMBER(K9),IF(K9>0,LN(K9),""),"") | R9: =IF(M9=1,INDEX(Quality!$AF:$AF,MATCH(A9,Quality!$A:$A,0)),"") -> 90 | S9: =IF(R9="","",IF(T9=1,0,R9)) -> 90 | T9: =IF(M9=1,INDEX(Quality!$AG:$AG,MATCH(A9,Quality!$A:$A,0)),0) -> 0 | U9: =IF(M9=1,INDEX(Quality!$AS:$AS,MATCH(A9,Quality!$A:$A,0)),"") -> 1 | V9: 0 | W9: 4.47734 | Y9: 90 | Z9: 0 | AA9: 1 | AB9: finished | AC9: 88 | AD9: 0 | AF9: 0 | AG9: 0 | AH9: =IF(AND(G9=AB9,IF(AND(ISNUMBER(H9),ISNUMBER(AC9)),ABS(N(H9)-N(AC9))<=Settings!$B$9*MAX(1,ABS(N(AC9))),AND(H9="",AC9="")),IF(AND(ISNUMBER(J9),ISNUMBER(AD9)),ABS(N(J9)-N(AD9))<=Settings!$B$9*MAX(1,ABS(N(AD9))),AND(J9="",AD9="")),IF(AND(ISNUMBER(K9),ISNUMBER(AE9)),ABS(N(K9)-N(AE9))<=Settings!$B$9*MAX(1,ABS(N(AE9))),AND(K9="",AE9="")),L9=AF9,I9=AG9),"ok","CHECK") -> ok | AI9: =IF(AND(IF(AND(ISNUMBER(O9),ISNUMBER(V9)),ABS(N(O9)-N(V9))<=Settings!$B$9*MAX(1,ABS(N(V9))),AND(O9="",V9="")),IF(AND(ISNUMBER(P9),ISNUMBER(W9)),ABS(N(P9)-N(W9))<=Settings!$B$9*MAX(1,ABS(N(W9))),AND(P9="",W9="")),IF(AND(ISNUMBER(Q9),ISNUMBER(X9)),ABS(N(Q9)-N(X9))<=Settings!$B$9*MAX(1,ABS(N(X9))),AND(Q9="",X9="")),IF(AND(ISNUMBER(R9),ISNUMBER(Y9)),ABS(N(R9)-N(Y9))<=Settings!$B$9*MAX(1,ABS(N(Y9))),AND(R9="",Y9="")),T9=Z9,IF(AND(ISNUMBER(U9),ISNUMBER(AA9)),ABS(N(U9)-N(AA9))<=Settings!$B$9*MAX(1,ABS(N(AA9))),AND(U9="",AA9=""))),"ok","CHECK") -> ok | AK9: =IF(ISNUMBER(P9),1,0) -> 1 | AL9: =COUNTIFS(Runs!$B$2:$B$61,B9,Runs!$E$2:$E$61,E9,Runs!$N$2:$N$61,N9,Runs!$AK$2:$AK$61,1) -> 2 | AM9: =IF(AK9=1,AVERAGEIFS(Runs!$P$2:$P$61,Runs!$B$2:$B$61,B9,Runs!$E$2:$E$61,E9,Runs!$N$2:$N$61,N9,Runs!$AK$2:$AK$61,1),"") -> 3.8064155 | AN9: =IF(AK9=1,IF(AL9>1,(P9-AM9)^2*AL9/(AL9-1),0),0) -> 0.90027078 | AO9: =IF(ISNUMBER(R9),1,0) -> 1 | AP9: =COUNTIFS(Runs!$B$2:$B$61,B9,Runs!$E$2:$E$61,E9,Runs!$N$2:$N$61,N9,Runs!$AO$2:$AO$61,1) -> 2 | AQ9: =IF(AO9=1,AVERAGEIFS(Runs!$R$2:$R$61,Runs!$B$2:$B$61,B9,Runs!$E$2:$E$61,E9,Runs!$N$2:$N$61,N9,Runs!$AO$2:$AO$61,1),"") -> 92 | AR9: =IF(AO9=1,IF(AP9>1,(R9-AQ9)^2*AP9/(AP9-1),0),0) -> 8 | AS9: =IF(ISNUMBER(J9),1,0) -> 1 | AT9: =COUNTIFS(Runs!$B$2:$B$61,B9,Runs!$E$2:$E$61,E9,Runs!$N$2:$N$61,N9,Runs!$AS$2:$AS$61,1) -> 2 | AU9: =IF(AS9=1,AVERAGEIFS(Runs!$J$2:$J$61,Runs!$B$2:$B$61,B9,Runs!$E$2:$E$61,E9,Runs!$N$2:$N$61,N9,Runs!$AS$2:$AS$61,1),"") -> 0 | AV9: =IF(AS9=1,IF(AT9>1,(J9-AU9)^2*AT9/(AT9-1),0),0) -> 0 | AW9: =IF(ISNUMBER(Q9),1,0) -> 0 | AX9: =COUNTIFS(Runs!$B$2:$B$61,B9,Runs!$E$2:$E$61,E9,Runs!$N$2:$N$61,N9,Runs!$AW$2:$AW$61,1) -> 0 | AY9: =IF(AW9=1,AVERAGEIFS(Runs!$Q$2:$Q$61,Runs!$B$2:$B$61,B9,Runs!$E$2:$E$61,E9,Runs!$N$2:$N$61,N9,Runs!$AW$2:$AW$61,1),"") | AZ9: =IF(AW9=1,IF(AX9>1,(Q9-AY9)^2*AX9/(AX9-1),0),0) -> 0
A10: 780140 | B10: gemma-q4 | C10: kanban-board | D10: interactive | E10: unseen | F10: 1 | G10: budget_exhausted | H10: 72 | I10: 0 | J10: 0.75 | K10: 405.5 | L10: 0 | M10: 1 | N10: =C10&"|"&D10 -> kanban-board|interactive | O10: =IF(G10="finished",0,1) -> 1 | P10: =IF(O10=0,LN(H10),"") | Q10: =IF(ISNUMBER(K10),IF(K10>0,LN(K10),""),"") -> 6.0051209 | R10: =IF(M10=1,INDEX(Quality!$AF:$AF,MATCH(A10,Quality!$A:$A,0)),"") -> 84 | S10: =IF(R10="","",IF(T10=1,0,R10)) -> 0 | T10: =IF(M10=1,INDEX(Quality!$AG:$AG,MATCH(A10,Quality!$A:$A,0)),0) -> 1 | U10: =IF(M10=1,INDEX(Quality!$AS:$AS,MATCH(A10,Quality!$A:$A,0)),"") -> 0.5 | V10: 1 | X10: 6.00512 | Y10: 84 | Z10: 1 | AA10: 0.5 | AB10: budget_exhausted | AC10: 72 | AD10: 0.75 | AE10: 405.5 | AF10: 0 | AG10: 0 | AH10: =IF(AND(G10=AB10,IF(AND(ISNUMBER(H10),ISNUMBER(AC10)),ABS(N(H10)-N(AC10))<=Settings!$B$9*MAX(1,ABS(N(AC10))),AND(H10="",AC10="")),IF(AND(ISNUMBER(J10),ISNUMBER(AD10)),ABS(N(J10)-N(AD10))<=Settings!$B$9*MAX(1,ABS(N(AD10))),AND(J10="",AD10="")),IF(AND(ISNUMBER(K10),ISNUMBER(AE10)),ABS(N(K10)-N(AE10))<=Settings!$B$9*MAX(1,ABS(N(AE10))),AND(K10="",AE10="")),L10=AF10,I10=AG10),"ok","CHECK") -> ok | AI10: =IF(AND(IF(AND(ISNUMBER(O10),ISNUMBER(V10)),ABS(N(O10)-N(V10))<=Settings!$B$9*MAX(1,ABS(N(V10))),AND(O10="",V10="")),IF(AND(ISNUMBER(P10),ISNUMBER(W10)),ABS(N(P10)-N(W10))<=Settings!$B$9*MAX(1,ABS(N(W10))),AND(P10="",W10="")),IF(AND(ISNUMBER(Q10),ISNUMBER(X10)),ABS(N(Q10)-N(X10))<=Settings!$B$9*MAX(1,ABS(N(X10))),AND(Q10="",X10="")),IF(AND(ISNUMBER(R10),ISNUMBER(Y10)),ABS(N(R10)-N(Y10))<=Settings!$B$9*MAX(1,ABS(N(Y10))),AND(R10="",Y10="")),T10=Z10,IF(AND(ISNUMBER(U10),ISNUMBER(AA10)),ABS(N(U10)-N(AA10))<=Settings!$B$9*MAX(1,ABS(N(AA10))),AND(U10="",AA10=""))),"ok","CHECK") -> ok | AK10: =IF(ISNUMBER(P10),1,0) -> 0 | AL10: =COUNTIFS(Runs!$B$2:$B$61,B10,Runs!$E$2:$E$61,E10,Runs!$N$2:$N$61,N10,Runs!$AK$2:$AK$61,1) -> 1 | AM10: =IF(AK10=1,AVERAGEIFS(Runs!$P$2:$P$61,Runs!$B$2:$B$61,B10,Runs!$E$2:$E$61,E10,Runs!$N$2:$N$61,N10,Runs!$AK$2:$AK$61,1),"") | AN10: =IF(AK10=1,IF(AL10>1,(P10-AM10)^2*AL10/(AL10-1),0),0) -> 0 | AO10: =IF(ISNUMBER(R10),1,0) -> 1 | AP10: =COUNTIFS(Runs!$B$2:$B$61,B10,Runs!$E$2:$E$61,E10,Runs!$N$2:$N$61,N10,Runs!$AO$2:$AO$61,1) -> 2 | AQ10: =IF(AO10=1,AVERAGEIFS(Runs!$R$2:$R$61,Runs!$B$2:$B$61,B10,Runs!$E$2:$E$61,E10,Runs!$N$2:$N$61,N10,Runs!$AO$2:$AO$61,1),"") -> 87 | AR10: =IF(AO10=1,IF(AP10>1,(R10-AQ10)^2*AP10/(AP10-1),0),0) -> 18 | AS10: =IF(ISNUMBER(J10),1,0) -> 1 | AT10: =COUNTIFS(Runs!$B$2:$B$61,B10,Runs!$E$2:$E$61,E10,Runs!$N$2:$N$61,N10,Runs!$AS$2:$AS$61,1) -> 2 | AU10: =IF(AS10=1,AVERAGEIFS(Runs!$J$2:$J$61,Runs!$B$2:$B$61,B10,Runs!$E$2:$E$61,E10,Runs!$N$2:$N$61,N10,Runs!$AS$2:$AS$61,1),"") -> 0.7083335 | AV10: =IF(AS10=1,IF(AT10>1,(J10-AU10)^2*AT10/(AT10-1),0),0) -> 0.0034721944 | AW10: =IF(ISNUMBER(Q10),1,0) -> 1 | AX10: =COUNTIFS(Runs!$B$2:$B$61,B10,Runs!$E$2:$E$61,E10,Runs!$N$2:$N$61,N10,Runs!$AW$2:$AW$61,1) -> 2 | AY10: =IF(AW10=1,AVERAGEIFS(Runs!$Q$2:$Q$61,Runs!$B$2:$B$61,B10,Runs!$E$2:$E$61,E10,Runs!$N$2:$N$61,N10,Runs!$AW$2:$AW$61,1),"") -> 5.9849924 | AZ10: =IF(AW10=1,IF(AX10>1,(Q10-AY10)^2*AX10/(AX10-1),0),0) -> 0.00081031336
A11: 705500 | B11: gemma-q4 | C11: kanban-board | D11: interactive | E11: unseen | F11: 2 | G11: finished | H11: 27 | I11: 0 | J11: 0.666667 | K11: 389.5 | L11: 0 | M11: 1 | N11: =C11&"|"&D11 -> kanban-board|interactive | O11: =IF(G11="finished",0,1) -> 0 | P11: =IF(O11=0,LN(H11),"") -> 3.2958369 | Q11: =IF(ISNUMBER(K11),IF(K11>0,LN(K11),""),"") -> 5.9648639 | R11: =IF(M11=1,INDEX(Quality!$AF:$AF,MATCH(A11,Quality!$A:$A,0)),"") -> 90 | S11: =IF(R11="","",IF(T11=1,0,R11)) -> 90 | T11: =IF(M11=1,INDEX(Quality!$AG:$AG,MATCH(A11,Quality!$A:$A,0)),0) -> 0 | U11: =IF(M11=1,INDEX(Quality!$AS:$AS,MATCH(A11,Quality!$A:$A,0)),"") -> 0.6 | V11: 0 | W11: 3.29584 | X11: 5.96486 | Y11: 90 | Z11: 0 | AA11: 0.6 | AB11: finished | AC11: 27 | AD11: 0.66666667 | AE11: 389.5 | AF11: 0 | AG11: 0 | AH11: =IF(AND(G11=AB11,IF(AND(ISNUMBER(H11),ISNUMBER(AC11)),ABS(N(H11)-N(AC11))<=Settings!$B$9*MAX(1,ABS(N(AC11))),AND(H11="",AC11="")),IF(AND(ISNUMBER(J11),ISNUMBER(AD11)),ABS(N(J11)-N(AD11))<=Settings!$B$9*MAX(1,ABS(N(AD11))),AND(J11="",AD11="")),IF(AND(ISNUMBER(K11),ISNUMBER(AE11)),ABS(N(K11)-N(AE11))<=Settings!$B$9*MAX(1,ABS(N(AE11))),AND(K11="",AE11="")),L11=AF11,I11=AG11),"ok","CHECK") -> ok | AI11: =IF(AND(IF(AND(ISNUMBER(O11),ISNUMBER(V11)),ABS(N(O11)-N(V11))<=Settings!$B$9*MAX(1,ABS(N(V11))),AND(O11="",V11="")),IF(AND(ISNUMBER(P11),ISNUMBER(W11)),ABS(N(P11)-N(W11))<=Settings!$B$9*MAX(1,ABS(N(W11))),AND(P11="",W11="")),IF(AND(ISNUMBER(Q11),ISNUMBER(X11)),ABS(N(Q11)-N(X11))<=Settings!$B$9*MAX(1,ABS(N(X11))),AND(Q11="",X11="")),IF(AND(ISNUMBER(R11),ISNUMBER(Y11)),ABS(N(R11)-N(Y11))<=Settings!$B$9*MAX(1,ABS(N(Y11))),AND(R11="",Y11="")),T11=Z11,IF(AND(ISNUMBER(U11),ISNUMBER(AA11)),ABS(N(U11)-N(AA11))<=Settings!$B$9*MAX(1,ABS(N(AA11))),AND(U11="",AA11=""))),"ok","CHECK") -> ok | AK11: =IF(ISNUMBER(P11),1,0) -> 1 | AL11: =COUNTIFS(Runs!$B$2:$B$61,B11,Runs!$E$2:$E$61,E11,Runs!$N$2:$N$61,N11,Runs!$AK$2:$AK$61,1) -> 1 | AM11: =IF(AK11=1,AVERAGEIFS(Runs!$P$2:$P$61,Runs!$B$2:$B$61,B11,Runs!$E$2:$E$61,E11,Runs!$N$2:$N$61,N11,Runs!$AK$2:$AK$61,1),"") -> 3.2958369 | AN11: =IF(AK11=1,IF(AL11>1,(P11-AM11)^2*AL11/(AL11-1),0),0) -> 0 | AO11: =IF(ISNUMBER(R11),1,0) -> 1 | AP11: =COUNTIFS(Runs!$B$2:$B$61,B11,Runs!$E$2:$E$61,E11,Runs!$N$2:$N$61,N11,Runs!$AO$2:$AO$61,1) -> 2 | AQ11: =IF(AO11=1,AVERAGEIFS(Runs!$R$2:$R$61,Runs!$B$2:$B$61,B11,Runs!$E$2:$E$61,E11,Runs!$N$2:$N$61,N11,Runs!$AO$2:$AO$61,1),"") -> 87 | AR11: =IF(AO11=1,IF(AP11>1,(R11-AQ11)^2*AP11/(AP11-1),0),0) -> 18 | AS11: =IF(ISNUMBER(J11),1,0) -> 1 | AT11: =COUNTIFS(Runs!$B$2:$B$61,B11,Runs!$E$2:$E$61,E11,Runs!$N$2:$N$61,N11,Runs!$AS$2:$AS$61,1) -> 2 | AU11: =IF(AS11=1,AVERAGEIFS(Runs!$J$2:$J$61,Runs!$B$2:$B$61,B11,Runs!$E$2:$E$61,E11,Runs!$N$2:$N$61,N11,Runs!$AS$2:$AS$61,1),"") -> 0.7083335 | AV11: =IF(AS11=1,IF(AT11>1,(J11-AU11)^2*AT11/(AT11-1),0),0) -> 0.0034721944 | AW11: =IF(ISNUMBER(Q11),1,0) -> 1 | AX11: =COUNTIFS(Runs!$B$2:$B$61,B11,Runs!$E$2:$E$61,E11,Runs!$N$2:$N$61,N11,Runs!$AW$2:$AW$61,1) -> 2 | AY11: =IF(AW11=1,AVERAGEIFS(Runs!$Q$2:$Q$61,Runs!$B$2:$B$61,B11,Runs!$E$2:$E$61,E11,Runs!$N$2:$N$61,N11,Runs!$AW$2:$AW$61,1),"") -> 5.9849924 | AZ11: =IF(AW11=1,IF(AX11>1,(Q11-AY11)^2*AX11/(AX11-1),0),0) -> 0.00081031336
A12: 284989 | B12: gemma-q4 | C12: kanban-board | D12: interactive | E12: seen | F12: 1 | G12: finished | H12: 47 | I12: 1 | J12: 0.978723 | K12: 155.5 | L12: 0 | M12: 1 | N12: =C12&"|"&D12 -> kanban-board|interactive | O12: =IF(G12="finished",0,1) -> 0 | P12: =IF(O12=0,LN(H12),"") -> 3.8501476 | Q12: =IF(ISNUMBER(K12),IF(K12>0,LN(K12),""),"") -> 5.0466457 | R12: =IF(M12=1,INDEX(Quality!$AF:$AF,MATCH(A12,Quality!$A:$A,0)),"") -> 90 | S12: =IF(R12="","",IF(T12=1,0,R12)) -> 90 | T12: =IF(M12=1,INDEX(Quality!$AG:$AG,MATCH(A12,Quality!$A:$A,0)),0) -> 0 | U12: =IF(M12=1,INDEX(Quality!$AS:$AS,MATCH(A12,Quality!$A:$A,0)),"") -> 0.9 | V12: 0 | W12: 3.85015 | X12: 5.04665 | Y12: 90 | Z12: 0 | AA12: 0.9 | AB12: finished | AC12: 47 | AD12: 0.9787234 | AE12: 155.5 | AF12: 0 | AG12: 1 | AH12: =IF(AND(G12=AB12,IF(AND(ISNUMBER(H12),ISNUMBER(AC12)),ABS(N(H12)-N(AC12))<=Settings!$B$9*MAX(1,ABS(N(AC12))),AND(H12="",AC12="")),IF(AND(ISNUMBER(J12),ISNUMBER(AD12)),ABS(N(J12)-N(AD12))<=Settings!$B$9*MAX(1,ABS(N(AD12))),AND(J12="",AD12="")),IF(AND(ISNUMBER(K12),ISNUMBER(AE12)),ABS(N(K12)-N(AE12))<=Settings!$B$9*MAX(1,ABS(N(AE12))),AND(K12="",AE12="")),L12=AF12,I12=AG12),"ok","CHECK") -> ok | AI12: =IF(AND(IF(AND(ISNUMBER(O12),ISNUMBER(V12)),ABS(N(O12)-N(V12))<=Settings!$B$9*MAX(1,ABS(N(V12))),AND(O12="",V12="")),IF(AND(ISNUMBER(P12),ISNUMBER(W12)),ABS(N(P12)-N(W12))<=Settings!$B$9*MAX(1,ABS(N(W12))),AND(P12="",W12="")),IF(AND(ISNUMBER(Q12),ISNUMBER(X12)),ABS(N(Q12)-N(X12))<=Settings!$B$9*MAX(1,ABS(N(X12))),AND(Q12="",X12="")),IF(AND(ISNUMBER(R12),ISNUMBER(Y12)),ABS(N(R12)-N(Y12))<=Settings!$B$9*MAX(1,ABS(N(Y12))),AND(R12="",Y12="")),T12=Z12,IF(AND(ISNUMBER(U12),ISNUMBER(AA12)),ABS(N(U12)-N(AA12))<=Settings!$B$9*MAX(1,ABS(N(AA12))),AND(U12="",AA12=""))),"ok","CHECK") -> ok | AK12: =IF(ISNUMBER(P12),1,0) -> 1 | AL12: =COUNTIFS(Runs!$B$2:$B$61,B12,Runs!$E$2:$E$61,E12,Runs!$N$2:$N$61,N12,Runs!$AK$2:$AK$61,1) -> 2 | AM12: =IF(AK12=1,AVERAGEIFS(Runs!$P$2:$P$61,Runs!$B$2:$B$61,B12,Runs!$E$2:$E$61,E12,Runs!$N$2:$N$61,N12,Runs!$AK$2:$AK$61,1),"") -> 3.8810853 | AN12: =IF(AK12=1,IF(AL12>1,(P12-AM12)^2*AL12/(AL12-1),0),0) -> 0.0019142828 | AO12: =IF(ISNUMBER(R12),1,0) -> 1 | AP12: =COUNTIFS(Runs!$B$2:$B$61,B12,Runs!$E$2:$E$61,E12,Runs!$N$2:$N$61,N12,Runs!$AO$2:$AO$61,1) -> 2 | AQ12: =IF(AO12=1,AVERAGEIFS(Runs!$R$2:$R$61,Runs!$B$2:$B$61,B12,Runs!$E$2:$E$61,E12,Runs!$N$2:$N$61,N12,Runs!$AO$2:$AO$61,1),"") -> 52 | AR12: =IF(AO12=1,IF(AP12>1,(R12-AQ12)^2*AP12/(AP12-1),0),0) -> 2888 | AS12: =IF(ISNUMBER(J12),1,0) -> 1 | AT12: =COUNTIFS(Runs!$B$2:$B$61,B12,Runs!$E$2:$E$61,E12,Runs!$N$2:$N$61,N12,Runs!$AS$2:$AS$61,1) -> 2 | AU12: =IF(AS12=1,AVERAGEIFS(Runs!$J$2:$J$61,Runs!$B$2:$B$61,B12,Runs!$E$2:$E$61,E12,Runs!$N$2:$N$61,N12,Runs!$AS$2:$AS$61,1),"") -> 0.9793615 | AV12: =IF(AS12=1,IF(AT12>1,(J12-AU12)^2*AT12/(AT12-1),0),0) -> 8.153645e-07 | AW12: =IF(ISNUMBER(Q12),1,0) -> 1 | AX12: =COUNTIFS(Runs!$B$2:$B$61,B12,Runs!$E$2:$E$61,E12,Runs!$N$2:$N$61,N12,Runs!$AW$2:$AW$61,1) -> 2 | AY12: =IF(AW12=1,AVERAGEIFS(Runs!$Q$2:$Q$61,Runs!$B$2:$B$61,B12,Runs!$E$2:$E$61,E12,Runs!$N$2:$N$61,N12,Runs!$AW$2:$AW$61,1),"") -> 4.9334636 | AZ12: =IF(AW12=1,IF(AX12>1,(Q12-AY12)^2*AX12/(AX12-1),0),0) -> 0.025620368
A13: 106538 | B13: gemma-q4 | C13: kanban-board | D13: interactive | E13: seen | F13: 2 | G13: finished | H13: 50 | I13: 0 | J13: 0.98 | K13: 124 | L13: 0 | M13: 1 | N13: =C13&"|"&D13 -> kanban-board|interactive | O13: =IF(G13="finished",0,1) -> 0 | P13: =IF(O13=0,LN(H13),"") -> 3.912023 | Q13: =IF(ISNUMBER(K13),IF(K13>0,LN(K13),""),"") -> 4.8202816 | R13: =IF(M13=1,INDEX(Quality!$AF:$AF,MATCH(A13,Quality!$A:$A,0)),"") -> 14 | S13: =IF(R13="","",IF(T13=1,0,R13)) -> 14 | T13: =IF(M13=1,INDEX(Quality!$AG:$AG,MATCH(A13,Quality!$A:$A,0)),0) -> 0 | U13: =IF(M13=1,INDEX(Quality!$AS:$AS,MATCH(A13,Quality!$A:$A,0)),"") -> 0.6 | V13: 0 | W13: 3.91202 | X13: 4.82028 | Y13: 14 | Z13: 0 | AA13: 0.6 | AB13: finished | AC13: 50 | AD13: 0.98 | AE13: 124 | AF13: 0 | AG13: 0 | AH13: =IF(AND(G13=AB13,IF(AND(ISNUMBER(H13),ISNUMBER(AC13)),ABS(N(H13)-N(AC13))<=Settings!$B$9*MAX(1,ABS(N(AC13))),AND(H13="",AC13="")),IF(AND(ISNUMBER(J13),ISNUMBER(AD13)),ABS(N(J13)-N(AD13))<=Settings!$B$9*MAX(1,ABS(N(AD13))),AND(J13="",AD13="")),IF(AND(ISNUMBER(K13),ISNUMBER(AE13)),ABS(N(K13)-N(AE13))<=Settings!$B$9*MAX(1,ABS(N(AE13))),AND(K13="",AE13="")),L13=AF13,I13=AG13),"ok","CHECK") -> ok | AI13: =IF(AND(IF(AND(ISNUMBER(O13),ISNUMBER(V13)),ABS(N(O13)-N(V13))<=Settings!$B$9*MAX(1,ABS(N(V13))),AND(O13="",V13="")),IF(AND(ISNUMBER(P13),ISNUMBER(W13)),ABS(N(P13)-N(W13))<=Settings!$B$9*MAX(1,ABS(N(W13))),AND(P13="",W13="")),IF(AND(ISNUMBER(Q13),ISNUMBER(X13)),ABS(N(Q13)-N(X13))<=Settings!$B$9*MAX(1,ABS(N(X13))),AND(Q13="",X13="")),IF(AND(ISNUMBER(R13),ISNUMBER(Y13)),ABS(N(R13)-N(Y13))<=Settings!$B$9*MAX(1,ABS(N(Y13))),AND(R13="",Y13="")),T13=Z13,IF(AND(ISNUMBER(U13),ISNUMBER(AA13)),ABS(N(U13)-N(AA13))<=Settings!$B$9*MAX(1,ABS(N(AA13))),AND(U13="",AA13=""))),"ok","CHECK") -> ok | AK13: =IF(ISNUMBER(P13),1,0) -> 1 | AL13: =COUNTIFS(Runs!$B$2:$B$61,B13,Runs!$E$2:$E$61,E13,Runs!$N$2:$N$61,N13,Runs!$AK$2:$AK$61,1) -> 2 | AM13: =IF(AK13=1,AVERAGEIFS(Runs!$P$2:$P$61,Runs!$B$2:$B$61,B13,Runs!$E$2:$E$61,E13,Runs!$N$2:$N$61,N13,Runs!$AK$2:$AK$61,1),"") -> 3.8810853 | AN13: =IF(AK13=1,IF(AL13>1,(P13-AM13)^2*AL13/(AL13-1),0),0) -> 0.0019142828 | AO13: =IF(ISNUMBER(R13),1,0) -> 1 | AP13: =COUNTIFS(Runs!$B$2:$B$61,B13,Runs!$E$2:$E$61,E13,Runs!$N$2:$N$61,N13,Runs!$AO$2:$AO$61,1) -> 2 | AQ13: =IF(AO13=1,AVERAGEIFS(Runs!$R$2:$R$61,Runs!$B$2:$B$61,B13,Runs!$E$2:$E$61,E13,Runs!$N$2:$N$61,N13,Runs!$AO$2:$AO$61,1),"") -> 52 | AR13: =IF(AO13=1,IF(AP13>1,(R13-AQ13)^2*AP13/(AP13-1),0),0) -> 2888 | AS13: =IF(ISNUMBER(J13),1,0) -> 1 | AT13: =COUNTIFS(Runs!$B$2:$B$61,B13,Runs!$E$2:$E$61,E13,Runs!$N$2:$N$61,N13,Runs!$AS$2:$AS$61,1) -> 2 | AU13: =IF(AS13=1,AVERAGEIFS(Runs!$J$2:$J$61,Runs!$B$2:$B$61,B13,Runs!$E$2:$E$61,E13,Runs!$N$2:$N$61,N13,Runs!$AS$2:$AS$61,1),"") -> 0.9793615 | AV13: =IF(AS13=1,IF(AT13>1,(J13-AU13)^2*AT13/(AT13-1),0),0) -> 8.153645e-07 | AW13: =IF(ISNUMBER(Q13),1,0) -> 1 | AX13: =COUNTIFS(Runs!$B$2:$B$61,B13,Runs!$E$2:$E$61,E13,Runs!$N$2:$N$61,N13,Runs!$AW$2:$AW$61,1) -> 2 | AY13: =IF(AW13=1,AVERAGEIFS(Runs!$Q$2:$Q$61,Runs!$B$2:$B$61,B13,Runs!$E$2:$E$61,E13,Runs!$N$2:$N$61,N13,Runs!$AW$2:$AW$61,1),"") -> 4.9334636 | AZ13: =IF(AW13=1,IF(AX13>1,(Q13-AY13)^2*AX13/(AX13-1),0),0) -> 0.025620368
A14: 496239 | B14: gemma-q4 | C14: kanban-board | D14: no_verification | E14: off | F14: 1 | G14: finished | H14: 99 | I14: 0 | J14: 0 | L14: 1 | M14: 1 | N14: =C14&"|"&D14 -> kanban-board|no_verification | O14: =IF(G14="finished",0,1) -> 0 | P14: =IF(O14=0,LN(H14),"") -> 4.5951199 | Q14: =IF(ISNUMBER(K14),IF(K14>0,LN(K14),""),"") | R14: =IF(M14=1,INDEX(Quality!$AF:$AF,MATCH(A14,Quality!$A:$A,0)),"") -> 6 | S14: =IF(R14="","",IF(T14=1,0,R14)) -> 6 | T14: =IF(M14=1,INDEX(Quality!$AG:$AG,MATCH(A14,Quality!$A:$A,0)),0) -> 0 | U14: =IF(M14=1,INDEX(Quality!$AS:$AS,MATCH(A14,Quality!$A:$A,0)),"") -> 0.6 | V14: 0 | W14: 4.59512 | Y14: 6 | Z14: 0 | AA14: 0.6 | AB14: finished | AC14: 99 | AD14: 0 | AF14: 1 | AG14: 0 | AH14: =IF(AND(G14=AB14,IF(AND(ISNUMBER(H14),ISNUMBER(AC14)),ABS(N(H14)-N(AC14))<=Settings!$B$9*MAX(1,ABS(N(AC14))),AND(H14="",AC14="")),IF(AND(ISNUMBER(J14),ISNUMBER(AD14)),ABS(N(J14)-N(AD14))<=Settings!$B$9*MAX(1,ABS(N(AD14))),AND(J14="",AD14="")),IF(AND(ISNUMBER(K14),ISNUMBER(AE14)),ABS(N(K14)-N(AE14))<=Settings!$B$9*MAX(1,ABS(N(AE14))),AND(K14="",AE14="")),L14=AF14,I14=AG14),"ok","CHECK") -> ok | AI14: =IF(AND(IF(AND(ISNUMBER(O14),ISNUMBER(V14)),ABS(N(O14)-N(V14))<=Settings!$B$9*MAX(1,ABS(N(V14))),AND(O14="",V14="")),IF(AND(ISNUMBER(P14),ISNUMBER(W14)),ABS(N(P14)-N(W14))<=Settings!$B$9*MAX(1,ABS(N(W14))),AND(P14="",W14="")),IF(AND(ISNUMBER(Q14),ISNUMBER(X14)),ABS(N(Q14)-N(X14))<=Settings!$B$9*MAX(1,ABS(N(X14))),AND(Q14="",X14="")),IF(AND(ISNUMBER(R14),ISNUMBER(Y14)),ABS(N(R14)-N(Y14))<=Settings!$B$9*MAX(1,ABS(N(Y14))),AND(R14="",Y14="")),T14=Z14,IF(AND(ISNUMBER(U14),ISNUMBER(AA14)),ABS(N(U14)-N(AA14))<=Settings!$B$9*MAX(1,ABS(N(AA14))),AND(U14="",AA14=""))),"ok","CHECK") -> ok | AK14: =IF(ISNUMBER(P14),1,0) -> 1 | AL14: =COUNTIFS(Runs!$B$2:$B$61,B14,Runs!$E$2:$E$61,E14,Runs!$N$2:$N$61,N14,Runs!$AK$2:$AK$61,1) -> 1 | AM14: =IF(AK14=1,AVERAGEIFS(Runs!$P$2:$P$61,Runs!$B$2:$B$61,B14,Runs!$E$2:$E$61,E14,Runs!$N$2:$N$61,N14,Runs!$AK$2:$AK$61,1),"") -> 4.5951199 | AN14: =IF(AK14=1,IF(AL14>1,(P14-AM14)^2*AL14/(AL14-1),0),0) -> 0 | AO14: =IF(ISNUMBER(R14),1,0) -> 1 | AP14: =COUNTIFS(Runs!$B$2:$B$61,B14,Runs!$E$2:$E$61,E14,Runs!$N$2:$N$61,N14,Runs!$AO$2:$AO$61,1) -> 2 | AQ14: =IF(AO14=1,AVERAGEIFS(Runs!$R$2:$R$61,Runs!$B$2:$B$61,B14,Runs!$E$2:$E$61,E14,Runs!$N$2:$N$61,N14,Runs!$AO$2:$AO$61,1),"") -> 5 | AR14: =IF(AO14=1,IF(AP14>1,(R14-AQ14)^2*AP14/(AP14-1),0),0) -> 2 | AS14: =IF(ISNUMBER(J14),1,0) -> 1 | AT14: =COUNTIFS(Runs!$B$2:$B$61,B14,Runs!$E$2:$E$61,E14,Runs!$N$2:$N$61,N14,Runs!$AS$2:$AS$61,1) -> 2 | AU14: =IF(AS14=1,AVERAGEIFS(Runs!$J$2:$J$61,Runs!$B$2:$B$61,B14,Runs!$E$2:$E$61,E14,Runs!$N$2:$N$61,N14,Runs!$AS$2:$AS$61,1),"") -> 0 | AV14: =IF(AS14=1,IF(AT14>1,(J14-AU14)^2*AT14/(AT14-1),0),0) -> 0 | AW14: =IF(ISNUMBER(Q14),1,0) -> 0 | AX14: =COUNTIFS(Runs!$B$2:$B$61,B14,Runs!$E$2:$E$61,E14,Runs!$N$2:$N$61,N14,Runs!$AW$2:$AW$61,1) -> 0 | AY14: =IF(AW14=1,AVERAGEIFS(Runs!$Q$2:$Q$61,Runs!$B$2:$B$61,B14,Runs!$E$2:$E$61,E14,Runs!$N$2:$N$61,N14,Runs!$AW$2:$AW$61,1),"") | AZ14: =IF(AW14=1,IF(AX14>1,(Q14-AY14)^2*AX14/(AX14-1),0),0) -> 0
A15: 153476 | B15: gemma-q4 | C15: kanban-board | D15: no_verification | E15: off | F15: 2 | G15: truncated_tool_args | H15: 98 | I15: 0 | J15: 0 | L15: 0 | M15: 1 | N15: =C15&"|"&D15 -> kanban-board|no_verification | O15: =IF(G15="finished",0,1) -> 1 | P15: =IF(O15=0,LN(H15),"") | Q15: =IF(ISNUMBER(K15),IF(K15>0,LN(K15),""),"") | R15: =IF(M15=1,INDEX(Quality!$AF:$AF,MATCH(A15,Quality!$A:$A,0)),"") -> 4 | S15: =IF(R15="","",IF(T15=1,0,R15)) -> 4 | T15: =IF(M15=1,INDEX(Quality!$AG:$AG,MATCH(A15,Quality!$A:$A,0)),0) -> 0 | U15: =IF(M15=1,INDEX(Quality!$AS:$AS,MATCH(A15,Quality!$A:$A,0)),"") -> 0.7 | V15: 1 | Y15: 4 | Z15: 0 | AA15: 0.7 | AB15: truncated_tool_args | AC15: 98 | AD15: 0 | AF15: 0 | AG15: 0 | AH15: =IF(AND(G15=AB15,IF(AND(ISNUMBER(H15),ISNUMBER(AC15)),ABS(N(H15)-N(AC15))<=Settings!$B$9*MAX(1,ABS(N(AC15))),AND(H15="",AC15="")),IF(AND(ISNUMBER(J15),ISNUMBER(AD15)),ABS(N(J15)-N(AD15))<=Settings!$B$9*MAX(1,ABS(N(AD15))),AND(J15="",AD15="")),IF(AND(ISNUMBER(K15),ISNUMBER(AE15)),ABS(N(K15)-N(AE15))<=Settings!$B$9*MAX(1,ABS(N(AE15))),AND(K15="",AE15="")),L15=AF15,I15=AG15),"ok","CHECK") -> ok | AI15: =IF(AND(IF(AND(ISNUMBER(O15),ISNUMBER(V15)),ABS(N(O15)-N(V15))<=Settings!$B$9*MAX(1,ABS(N(V15))),AND(O15="",V15="")),IF(AND(ISNUMBER(P15),ISNUMBER(W15)),ABS(N(P15)-N(W15))<=Settings!$B$9*MAX(1,ABS(N(W15))),AND(P15="",W15="")),IF(AND(ISNUMBER(Q15),ISNUMBER(X15)),ABS(N(Q15)-N(X15))<=Settings!$B$9*MAX(1,ABS(N(X15))),AND(Q15="",X15="")),IF(AND(ISNUMBER(R15),ISNUMBER(Y15)),ABS(N(R15)-N(Y15))<=Settings!$B$9*MAX(1,ABS(N(Y15))),AND(R15="",Y15="")),T15=Z15,IF(AND(ISNUMBER(U15),ISNUMBER(AA15)),ABS(N(U15)-N(AA15))<=Settings!$B$9*MAX(1,ABS(N(AA15))),AND(U15="",AA15=""))),"ok","CHECK") -> ok | AK15: =IF(ISNUMBER(P15),1,0) -> 0 | AL15: =COUNTIFS(Runs!$B$2:$B$61,B15,Runs!$E$2:$E$61,E15,Runs!$N$2:$N$61,N15,Runs!$AK$2:$AK$61,1) -> 1 | AM15: =IF(AK15=1,AVERAGEIFS(Runs!$P$2:$P$61,Runs!$B$2:$B$61,B15,Runs!$E$2:$E$61,E15,Runs!$N$2:$N$61,N15,Runs!$AK$2:$AK$61,1),"") | AN15: =IF(AK15=1,IF(AL15>1,(P15-AM15)^2*AL15/(AL15-1),0),0) -> 0 | AO15: =IF(ISNUMBER(R15),1,0) -> 1 | AP15: =COUNTIFS(Runs!$B$2:$B$61,B15,Runs!$E$2:$E$61,E15,Runs!$N$2:$N$61,N15,Runs!$AO$2:$AO$61,1) -> 2 | AQ15: =IF(AO15=1,AVERAGEIFS(Runs!$R$2:$R$61,Runs!$B$2:$B$61,B15,Runs!$E$2:$E$61,E15,Runs!$N$2:$N$61,N15,Runs!$AO$2:$AO$61,1),"") -> 5 | AR15: =IF(AO15=1,IF(AP15>1,(R15-AQ15)^2*AP15/(AP15-1),0),0) -> 2 | AS15: =IF(ISNUMBER(J15),1,0) -> 1 | AT15: =COUNTIFS(Runs!$B$2:$B$61,B15,Runs!$E$2:$E$61,E15,Runs!$N$2:$N$61,N15,Runs!$AS$2:$AS$61,1) -> 2 | AU15: =IF(AS15=1,AVERAGEIFS(Runs!$J$2:$J$61,Runs!$B$2:$B$61,B15,Runs!$E$2:$E$61,E15,Runs!$N$2:$N$61,N15,Runs!$AS$2:$AS$61,1),"") -> 0 | AV15: =IF(AS15=1,IF(AT15>1,(J15-AU15)^2*AT15/(AT15-1),0),0) -> 0 | AW15: =IF(ISNUMBER(Q15),1,0) -> 0 | AX15: =COUNTIFS(Runs!$B$2:$B$61,B15,Runs!$E$2:$E$61,E15,Runs!$N$2:$N$61,N15,Runs!$AW$2:$AW$61,1) -> 0 | AY15: =IF(AW15=1,AVERAGEIFS(Runs!$Q$2:$Q$61,Runs!$B$2:$B$61,B15,Runs!$E$2:$E$61,E15,Runs!$N$2:$N$61,N15,Runs!$AW$2:$AW$61,1),"") | AZ15: =IF(AW15=1,IF(AX15>1,(Q15-AY15)^2*AX15/(AX15-1),0),0) -> 0
A16: 978461 | B16: gemma-q4 | C16: kanban-board | D16: no_verification | E16: unseen | F16: 1 | G16: truncated_no_tool_call | H16: 80 | I16: 1 | J16: 0.6875 | K16: 383 | L16: 1 | M16: 1 | N16: =C16&"|"&D16 -> kanban-board|no_verification | O16: =IF(G16="finished",0,1) -> 1 | P16: =IF(O16=0,LN(H16),"") | Q16: =IF(ISNUMBER(K16),IF(K16>0,LN(K16),""),"") -> 5.948035 | R16: =IF(M16=1,INDEX(Quality!$AF:$AF,MATCH(A16,Quality!$A:$A,0)),"") -> 84 | S16: =IF(R16="","",IF(T16=1,0,R16)) -> 84 | T16: =IF(M16=1,INDEX(Quality!$AG:$AG,MATCH(A16,Quality!$A:$A,0)),0) -> 0 | U16: =IF(M16=1,INDEX(Quality!$AS:$AS,MATCH(A16,Quality!$A:$A,0)),"") -> 0.8 | V16: 1 | X16: 5.94803 | Y16: 84 | Z16: 0 | AA16: 0.8 | AB16: truncated_no_tool_call | AC16: 80 | AD16: 0.6875 | AE16: 383 | AF16: 1 | AG16: 1 | AH16: =IF(AND(G16=AB16,IF(AND(ISNUMBER(H16),ISNUMBER(AC16)),ABS(N(H16)-N(AC16))<=Settings!$B$9*MAX(1,ABS(N(AC16))),AND(H16="",AC16="")),IF(AND(ISNUMBER(J16),ISNUMBER(AD16)),ABS(N(J16)-N(AD16))<=Settings!$B$9*MAX(1,ABS(N(AD16))),AND(J16="",AD16="")),IF(AND(ISNUMBER(K16),ISNUMBER(AE16)),ABS(N(K16)-N(AE16))<=Settings!$B$9*MAX(1,ABS(N(AE16))),AND(K16="",AE16="")),L16=AF16,I16=AG16),"ok","CHECK") -> ok | AI16: =IF(AND(IF(AND(ISNUMBER(O16),ISNUMBER(V16)),ABS(N(O16)-N(V16))<=Settings!$B$9*MAX(1,ABS(N(V16))),AND(O16="",V16="")),IF(AND(ISNUMBER(P16),ISNUMBER(W16)),ABS(N(P16)-N(W16))<=Settings!$B$9*MAX(1,ABS(N(W16))),AND(P16="",W16="")),IF(AND(ISNUMBER(Q16),ISNUMBER(X16)),ABS(N(Q16)-N(X16))<=Settings!$B$9*MAX(1,ABS(N(X16))),AND(Q16="",X16="")),IF(AND(ISNUMBER(R16),ISNUMBER(Y16)),ABS(N(R16)-N(Y16))<=Settings!$B$9*MAX(1,ABS(N(Y16))),AND(R16="",Y16="")),T16=Z16,IF(AND(ISNUMBER(U16),ISNUMBER(AA16)),ABS(N(U16)-N(AA16))<=Settings!$B$9*MAX(1,ABS(N(AA16))),AND(U16="",AA16=""))),"ok","CHECK") -> ok | AK16: =IF(ISNUMBER(P16),1,0) -> 0 | AL16: =COUNTIFS(Runs!$B$2:$B$61,B16,Runs!$E$2:$E$61,E16,Runs!$N$2:$N$61,N16,Runs!$AK$2:$AK$61,1) -> 0 | AM16: =IF(AK16=1,AVERAGEIFS(Runs!$P$2:$P$61,Runs!$B$2:$B$61,B16,Runs!$E$2:$E$61,E16,Runs!$N$2:$N$61,N16,Runs!$AK$2:$AK$61,1),"") | AN16: =IF(AK16=1,IF(AL16>1,(P16-AM16)^2*AL16/(AL16-1),0),0) -> 0 | AO16: =IF(ISNUMBER(R16),1,0) -> 1 | AP16: =COUNTIFS(Runs!$B$2:$B$61,B16,Runs!$E$2:$E$61,E16,Runs!$N$2:$N$61,N16,Runs!$AO$2:$AO$61,1) -> 2 | AQ16: =IF(AO16=1,AVERAGEIFS(Runs!$R$2:$R$61,Runs!$B$2:$B$61,B16,Runs!$E$2:$E$61,E16,Runs!$N$2:$N$61,N16,Runs!$AO$2:$AO$61,1),"") -> 44 | AR16: =IF(AO16=1,IF(AP16>1,(R16-AQ16)^2*AP16/(AP16-1),0),0) -> 3200 | AS16: =IF(ISNUMBER(J16),1,0) -> 1 | AT16: =COUNTIFS(Runs!$B$2:$B$61,B16,Runs!$E$2:$E$61,E16,Runs!$N$2:$N$61,N16,Runs!$AS$2:$AS$61,1) -> 2 | AU16: =IF(AS16=1,AVERAGEIFS(Runs!$J$2:$J$61,Runs!$B$2:$B$61,B16,Runs!$E$2:$E$61,E16,Runs!$N$2:$N$61,N16,Runs!$AS$2:$AS$61,1),"") -> 0.724347 | AV16: =IF(AS16=1,IF(AT16>1,(J16-AU16)^2*AT16/(AT16-1),0),0) -> 0.0027154028 | AW16: =IF(ISNUMBER(Q16),1,0) -> 1 | AX16: =COUNTIFS(Runs!$B$2:$B$61,B16,Runs!$E$2:$E$61,E16,Runs!$N$2:$N$61,N16,Runs!$AW$2:$AW$61,1) -> 2 | AY16: =IF(AW16=1,AVERAGEIFS(Runs!$Q$2:$Q$61,Runs!$B$2:$B$61,B16,Runs!$E$2:$E$61,E16,Runs!$N$2:$N$61,N16,Runs!$AW$2:$AW$61,1),"") -> 5.930769 | AZ16: =IF(AW16=1,IF(AX16>1,(Q16-AY16)^2*AX16/(AX16-1),0),0) -> 0.00059622894
A17: 238292 | B17: gemma-q4 | C17: kanban-board | D17: no_verification | E17: unseen | F17: 2 | G17: runaway_no_tool_call | H17: 67 | I17: 0 | J17: 0.761194 | K17: 370 | L17: 0 | M17: 1 | N17: =C17&"|"&D17 -> kanban-board|no_verification | O17: =IF(G17="finished",0,1) -> 1 | P17: =IF(O17=0,LN(H17),"") | Q17: =IF(ISNUMBER(K17),IF(K17>0,LN(K17),""),"") -> 5.913503 | R17: =IF(M17=1,INDEX(Quality!$AF:$AF,MATCH(A17,Quality!$A:$A,0)),"") -> 4 | S17: =IF(R17="","",IF(T17=1,0,R17)) -> 0 | T17: =IF(M17=1,INDEX(Quality!$AG:$AG,MATCH(A17,Quality!$A:$A,0)),0) -> 1 | U17: =IF(M17=1,INDEX(Quality!$AS:$AS,MATCH(A17,Quality!$A:$A,0)),"") -> 0.4 | V17: 1 | X17: 5.9135 | Y17: 4 | Z17: 1 | AA17: 0.4 | AB17: runaway_no_tool_call | AC17: 67 | AD17: 0.76119403 | AE17: 370 | AF17: 0 | AG17: 0 | AH17: =IF(AND(G17=AB17,IF(AND(ISNUMBER(H17),ISNUMBER(AC17)),ABS(N(H17)-N(AC17))<=Settings!$B$9*MAX(1,ABS(N(AC17))),AND(H17="",AC17="")),IF(AND(ISNUMBER(J17),ISNUMBER(AD17)),ABS(N(J17)-N(AD17))<=Settings!$B$9*MAX(1,ABS(N(AD17))),AND(J17="",AD17="")),IF(AND(ISNUMBER(K17),ISNUMBER(AE17)),ABS(N(K17)-N(AE17))<=Settings!$B$9*MAX(1,ABS(N(AE17))),AND(K17="",AE17="")),L17=AF17,I17=AG17),"ok","CHECK") -> ok | AI17: =IF(AND(IF(AND(ISNUMBER(O17),ISNUMBER(V17)),ABS(N(O17)-N(V17))<=Settings!$B$9*MAX(1,ABS(N(V17))),AND(O17="",V17="")),IF(AND(ISNUMBER(P17),ISNUMBER(W17)),ABS(N(P17)-N(W17))<=Settings!$B$9*MAX(1,ABS(N(W17))),AND(P17="",W17="")),IF(AND(ISNUMBER(Q17),ISNUMBER(X17)),ABS(N(Q17)-N(X17))<=Settings!$B$9*MAX(1,ABS(N(X17))),AND(Q17="",X17="")),IF(AND(ISNUMBER(R17),ISNUMBER(Y17)),ABS(N(R17)-N(Y17))<=Settings!$B$9*MAX(1,ABS(N(Y17))),AND(R17="",Y17="")),T17=Z17,IF(AND(ISNUMBER(U17),ISNUMBER(AA17)),ABS(N(U17)-N(AA17))<=Settings!$B$9*MAX(1,ABS(N(AA17))),AND(U17="",AA17=""))),"ok","CHECK") -> ok | AK17: =IF(ISNUMBER(P17),1,0) -> 0 | AL17: =COUNTIFS(Runs!$B$2:$B$61,B17,Runs!$E$2:$E$61,E17,Runs!$N$2:$N$61,N17,Runs!$AK$2:$AK$61,1) -> 0 | AM17: =IF(AK17=1,AVERAGEIFS(Runs!$P$2:$P$61,Runs!$B$2:$B$61,B17,Runs!$E$2:$E$61,E17,Runs!$N$2:$N$61,N17,Runs!$AK$2:$AK$61,1),"") | AN17: =IF(AK17=1,IF(AL17>1,(P17-AM17)^2*AL17/(AL17-1),0),0) -> 0 | AO17: =IF(ISNUMBER(R17),1,0) -> 1 | AP17: =COUNTIFS(Runs!$B$2:$B$61,B17,Runs!$E$2:$E$61,E17,Runs!$N$2:$N$61,N17,Runs!$AO$2:$AO$61,1) -> 2 | AQ17: =IF(AO17=1,AVERAGEIFS(Runs!$R$2:$R$61,Runs!$B$2:$B$61,B17,Runs!$E$2:$E$61,E17,Runs!$N$2:$N$61,N17,Runs!$AO$2:$AO$61,1),"") -> 44 | AR17: =IF(AO17=1,IF(AP17>1,(R17-AQ17)^2*AP17/(AP17-1),0),0) -> 3200 | AS17: =IF(ISNUMBER(J17),1,0) -> 1 | AT17: =COUNTIFS(Runs!$B$2:$B$61,B17,Runs!$E$2:$E$61,E17,Runs!$N$2:$N$61,N17,Runs!$AS$2:$AS$61,1) -> 2 | AU17: =IF(AS17=1,AVERAGEIFS(Runs!$J$2:$J$61,Runs!$B$2:$B$61,B17,Runs!$E$2:$E$61,E17,Runs!$N$2:$N$61,N17,Runs!$AS$2:$AS$61,1),"") -> 0.724347 | AV17: =IF(AS17=1,IF(AT17>1,(J17-AU17)^2*AT17/(AT17-1),0),0) -> 0.0027154028 | AW17: =IF(ISNUMBER(Q17),1,0) -> 1 | AX17: =COUNTIFS(Runs!$B$2:$B$61,B17,Runs!$E$2:$E$61,E17,Runs!$N$2:$N$61,N17,Runs!$AW$2:$AW$61,1) -> 2 | AY17: =IF(AW17=1,AVERAGEIFS(Runs!$Q$2:$Q$61,Runs!$B$2:$B$61,B17,Runs!$E$2:$E$61,E17,Runs!$N$2:$N$61,N17,Runs!$AW$2:$AW$61,1),"") -> 5.930769 | AZ17: =IF(AW17=1,IF(AX17>1,(Q17-AY17)^2*AX17/(AX17-1),0),0) -> 0.00059622894
A18: 936589 | B18: gemma-q4 | C18: kanban-board | D18: no_verification | E18: seen | F18: 1 | G18: budget_exhausted | H18: 31 | I18: 0 | J18: 0.967742 | K18: 116 | L18: 0 | M18: 1 | N18: =C18&"|"&D18 -> kanban-board|no_verification | O18: =IF(G18="finished",0,1) -> 1 | P18: =IF(O18=0,LN(H18),"") | Q18: =IF(ISNUMBER(K18),IF(K18>0,LN(K18),""),"") -> 4.7535902 | R18: =IF(M18=1,INDEX(Quality!$AF:$AF,MATCH(A18,Quality!$A:$A,0)),"") -> 90 | S18: =IF(R18="","",IF(T18=1,0,R18)) -> 0 | T18: =IF(M18=1,INDEX(Quality!$AG:$AG,MATCH(A18,Quality!$A:$A,0)),0) -> 1 | U18: =IF(M18=1,INDEX(Quality!$AS:$AS,MATCH(A18,Quality!$A:$A,0)),"") -> 0.8 | V18: 1 | X18: 4.75359 | Y18: 90 | Z18: 1 | AA18: 0.8 | AB18: budget_exhausted | AC18: 31 | AD18: 0.96774194 | AE18: 116 | AF18: 0 | AG18: 0 | AH18: =IF(AND(G18=AB18,IF(AND(ISNUMBER(H18),ISNUMBER(AC18)),ABS(N(H18)-N(AC18))<=Settings!$B$9*MAX(1,ABS(N(AC18))),AND(H18="",AC18="")),IF(AND(ISNUMBER(J18),ISNUMBER(AD18)),ABS(N(J18)-N(AD18))<=Settings!$B$9*MAX(1,ABS(N(AD18))),AND(J18="",AD18="")),IF(AND(ISNUMBER(K18),ISNUMBER(AE18)),ABS(N(K18)-N(AE18))<=Settings!$B$9*MAX(1,ABS(N(AE18))),AND(K18="",AE18="")),L18=AF18,I18=AG18),"ok","CHECK") -> ok | AI18: =IF(AND(IF(AND(ISNUMBER(O18),ISNUMBER(V18)),ABS(N(O18)-N(V18))<=Settings!$B$9*MAX(1,ABS(N(V18))),AND(O18="",V18="")),IF(AND(ISNUMBER(P18),ISNUMBER(W18)),ABS(N(P18)-N(W18))<=Settings!$B$9*MAX(1,ABS(N(W18))),AND(P18="",W18="")),IF(AND(ISNUMBER(Q18),ISNUMBER(X18)),ABS(N(Q18)-N(X18))<=Settings!$B$9*MAX(1,ABS(N(X18))),AND(Q18="",X18="")),IF(AND(ISNUMBER(R18),ISNUMBER(Y18)),ABS(N(R18)-N(Y18))<=Settings!$B$9*MAX(1,ABS(N(Y18))),AND(R18="",Y18="")),T18=Z18,IF(AND(ISNUMBER(U18),ISNUMBER(AA18)),ABS(N(U18)-N(AA18))<=Settings!$B$9*MAX(1,ABS(N(AA18))),AND(U18="",AA18=""))),"ok","CHECK") -> ok | AK18: =IF(ISNUMBER(P18),1,0) -> 0 | AL18: =COUNTIFS(Runs!$B$2:$B$61,B18,Runs!$E$2:$E$61,E18,Runs!$N$2:$N$61,N18,Runs!$AK$2:$AK$61,1) -> 1 | AM18: =IF(AK18=1,AVERAGEIFS(Runs!$P$2:$P$61,Runs!$B$2:$B$61,B18,Runs!$E$2:$E$61,E18,Runs!$N$2:$N$61,N18,Runs!$AK$2:$AK$61,1),"") | AN18: =IF(AK18=1,IF(AL18>1,(P18-AM18)^2*AL18/(AL18-1),0),0) -> 0 | AO18: =IF(ISNUMBER(R18),1,0) -> 1 | AP18: =COUNTIFS(Runs!$B$2:$B$61,B18,Runs!$E$2:$E$61,E18,Runs!$N$2:$N$61,N18,Runs!$AO$2:$AO$61,1) -> 2 | AQ18: =IF(AO18=1,AVERAGEIFS(Runs!$R$2:$R$61,Runs!$B$2:$B$61,B18,Runs!$E$2:$E$61,E18,Runs!$N$2:$N$61,N18,Runs!$AO$2:$AO$61,1),"") -> 91 | AR18: =IF(AO18=1,IF(AP18>1,(R18-AQ18)^2*AP18/(AP18-1),0),0) -> 2 | AS18: =IF(ISNUMBER(J18),1,0) -> 1 | AT18: =COUNTIFS(Runs!$B$2:$B$61,B18,Runs!$E$2:$E$61,E18,Runs!$N$2:$N$61,N18,Runs!$AS$2:$AS$61,1) -> 2 | AU18: =IF(AS18=1,AVERAGEIFS(Runs!$J$2:$J$61,Runs!$B$2:$B$61,B18,Runs!$E$2:$E$61,E18,Runs!$N$2:$N$61,N18,Runs!$AS$2:$AS$61,1),"") -> 0.983871 | AV18: =IF(AS18=1,IF(AT18>1,(J18-AU18)^2*AT18/(AT18-1),0),0) -> 0.00052028928 | AW18: =IF(ISNUMBER(Q18),1,0) -> 1 | AX18: =COUNTIFS(Runs!$B$2:$B$61,B18,Runs!$E$2:$E$61,E18,Runs!$N$2:$N$61,N18,Runs!$AW$2:$AW$61,1) -> 2 | AY18: =IF(AW18=1,AVERAGEIFS(Runs!$Q$2:$Q$61,Runs!$B$2:$B$61,B18,Runs!$E$2:$E$61,E18,Runs!$N$2:$N$61,N18,Runs!$AW$2:$AW$61,1),"") -> 4.8787682 | AZ18: =IF(AW18=1,IF(AX18>1,(Q18-AY18)^2*AX18/(AX18-1),0),0) -> 0.031339092
